Workbook

Sheet Drivers
B5: 01A-UGRA-MCAULEY
B6: 1A-UGRA-MCAULEY
T7: Racing
T8: Position | U8: Top | V8: Mid | W8: Bot
B9: Total Points | T9: 1 | U9: 50 | V9: 25 | W9: 12
B10: Driver | C10: R1A | D10: R1B | E10: R2A | F10: R2B | G10: R3A | H10: R3B | I10: R4A | J10: R4B | K10: R5A | L10: R5B | M10: R6A | N10: R6B | O10: R7A | P10: R7B | Q10: Total | R10: Avg | T10: 2 | U10: 45 | V10: 22 | W10: 9
B11: 01C-UGRA-KHAN | C11: =SUMIF(Top!$W$5:$W$168,$B11,Top!X$5:X$167)+SUMIF(Mid!$W$5:$W$168,$B11,Mid!X$5:X$167) -> 0 | D11: =SUMIF(Top!$W$5:$W$168,$B11,Top!Y$5:Y$167)+SUMIF(Mid!$W$5:$W$168,$B11,Mid!Y$5:Y$167) -> 0 | E11: =SUMIF(Top!$W$5:$W$168,$B11,Top!Z$5:Z$167)+SUMIF(Mid!$W$5:$W$168,$B11,Mid!Z$5:Z$167) -> 51 | F11: =SUMIF(Top!$W$5:$W$168,$B11,Top!AA$5:AA$167)+SUMIF(Mid!$W$5:$W$168,$B11,Mid!AA$5:AA$167) -> 0 | G11: =SUMIF(Top!$W$5:$W$168,$B11,Top!AB$5:AB$167)+SUMIF(Mid!$W$5:$W$168,$B11,Mid!AB$5:AB$167) -> 0 | H11: =SUMIF(Top!$W$5:$W$168,$B11,Top!AC$5:AC$167)+SUMIF(Mid!$W$5:$W$168,$B11,Mid!AC$5:AC$167) -> 0 | I11: =SUMIF(Top!$W$5:$W$168,$B11,Top!AD$5:AD$167)+SUMIF(Mid!$W$5:$W$168,$B11,Mid!AD$5:AD$167) -> 0 | J11: =SUMIF(Top!$W$5:$W$168,$B11,Top!AE$5:AE$167)+SUMIF(Mid!$W$5:$W$168,$B11,Mid!AE$5:AE$167) -> 0 | ... P11: =SUMIF(Top!$W$5:$W$168,$B11,Top!AK$5:AK$167)+SUMIF(Mid!$W$5:$W$168,$B11,Mid!AK$5:AK$167) -> 0 | Q11: =SUM(C11:P11) -> 51 | R11: =IF(Q11=0,0,Q11/COUNTIF(C11:P11,">0")) -> 51 | T11: 3 | U11: 42 | V11: 20 | W11: 7
B12: 40B-VIGO-VEIRO | C12: =SUMIF(Top!$W$5:$W$168,$B12,Top!X$5:X$167)+SUMIF(Mid!$W$5:$W$168,$B12,Mid!X$5:X$167) -> 0 | D12: =SUMIF(Top!$W$5:$W$168,$B12,Top!Y$5:Y$167)+SUMIF(Mid!$W$5:$W$168,$B12,Mid!Y$5:Y$167) -> 50 | E12: =SUMIF(Top!$W$5:$W$168,$B12,Top!Z$5:Z$167)+SUMIF(Mid!$W$5:$W$168,$B12,Mid!Z$5:Z$167) -> 0 | F12: =SUMIF(Top!$W$5:$W$168,$B12,Top!AA$5:AA$167)+SUMIF(Mid!$W$5:$W$168,$B12,Mid!AA$5:AA$167) -> 25 | G12: =SUMIF(Top!$W$5:$W$168,$B12,Top!AB$5:AB$167)+SUMIF(Mid!$W$5:$W$168,$B12,Mid!AB$5:AB$167) -> 0 | H12: =SUMIF(Top!$W$5:$W$168,$B12,Top!AC$5:AC$167)+SUMIF(Mid!$W$5:$W$168,$B12,Mid!AC$5:AC$167) -> 0 | I12: =SUMIF(Top!$W$5:$W$168,$B12,Top!AD$5:AD$167)+SUMIF(Mid!$W$5:$W$168,$B12,Mid!AD$5:AD$167) -> 0 | J12: =SUMIF(Top!$W$5:$W$168,$B12,Top!AE$5:AE$167)+SUMIF(Mid!$W$5:$W$168,$B12,Mid!AE$5:AE$167) -> 0 | ... P12: =SUMIF(Top!$W$5:$W$168,$B12,Top!AK$5:AK$167)+SUMIF(Mid!$W$5:$W$168,$B12,Mid!AK$5:AK$167) -> 0 | Q12: =SUM(C12:P12) -> 75 | R12: =IF(Q12=0,0,Q12/COUNTIF(C12:P12,">0")) -> 37.5 | T12: 4 | U12: 40 | V12: 18 | W12: 5
B13: 02A-STON-BHURJI | C13: =SUMIF(Top!$W$5:$W$168,$B13,Top!X$5:X$167)+SUMIF(Mid!$W$5:$W$168,$B13,Mid!X$5:X$167) -> 0 | D13: =SUMIF(Top!$W$5:$W$168,$B13,Top!Y$5:Y$167)+SUMIF(Mid!$W$5:$W$168,$B13,Mid!Y$5:Y$167) -> 47 | E13: =SUMIF(Top!$W$5:$W$168,$B13,Top!Z$5:Z$167)+SUMIF(Mid!$W$5:$W$168,$B13,Mid!Z$5:Z$167) -> 0 | F13: =SUMIF(Top!$W$5:$W$168,$B13,Top!AA$5:AA$167)+SUMIF(Mid!$W$5:$W$168,$B13,Mid!AA$5:AA$167) -> 0 | G13: =SUMIF(Top!$W$5:$W$168,$B13,Top!AB$5:AB$167)+SUMIF(Mid!$W$5:$W$168,$B13,Mid!AB$5:AB$167) -> 0 | H13: =SUMIF(Top!$W$5:$W$168,$B13,Top!AC$5:AC$167)+SUMIF(Mid!$W$5:$W$168,$B13,Mid!AC$5:AC$167) -> 0 | I13: =SUMIF(Top!$W$5:$W$168,$B13,Top!AD$5:AD$167)+SUMIF(Mid!$W$5:$W$168,$B13,Mid!AD$5:AD$167) -> 0 | J13: =SUMIF(Top!$W$5:$W$168,$B13,Top!AE$5:AE$167)+SUMIF(Mid!$W$5:$W$168,$B13,Mid!AE$5:AE$167) -> 0 | ... P13: =SUMIF(Top!$W$5:$W$168,$B13,Top!AK$5:AK$167)+SUMIF(Mid!$W$5:$W$168,$B13,Mid!AK$5:AK$167) -> 0 | Q13: =SUM(C13:P13) -> 47 | R13: =IF(Q13=0,0,Q13/COUNTIF(C13:P13,">0")) -> 47 | T13: 5 | U13: 38 | V13: 16 | W13: 4
B14: 02C-STON-WHITTAKER-CAMPIGOTTO | C14: =SUMIF(Top!$W$5:$W$168,$B14,Top!X$5:X$167)+SUMIF(Mid!$W$5:$W$168,$B14,Mid!X$5:X$167) -> 0 | D14: =SUMIF(Top!$W$5:$W$168,$B14,Top!Y$5:Y$167)+SUMIF(Mid!$W$5:$W$168,$B14,Mid!Y$5:Y$167) -> 0 | E14: =SUMIF(Top!$W$5:$W$168,$B14,Top!Z$5:Z$167)+SUMIF(Mid!$W$5:$W$168,$B14,Mid!Z$5:Z$167) -> 46 | F14: =SUMIF(Top!$W$5:$W$168,$B14,Top!AA$5:AA$167)+SUMIF(Mid!$W$5:$W$168,$B14,Mid!AA$5:AA$167) -> 0 | G14: =SUMIF(Top!$W$5:$W$168,$B14,Top!AB$5:AB$167)+SUMIF(Mid!$W$5:$W$168,$B14,Mid!AB$5:AB$167) -> 0 | H14: =SUMIF(Top!$W$5:$W$168,$B14,Top!AC$5:AC$167)+SUMIF(Mid!$W$5:$W$168,$B14,Mid!AC$5:AC$167) -> 0 | I14: =SUMIF(Top!$W$5:$W$168,$B14,Top!AD$5:AD$167)+SUMIF(Mid!$W$5:$W$168,$B14,Mid!AD$5:AD$167) -> 0 | J14: =SUMIF(Top!$W$5:$W$168,$B14,Top!AE$5:AE$167)+SUMIF(Mid!$W$5:$W$168,$B14,Mid!AE$5:AE$167) -> 0 | ... P14: =SUMIF(Top!$W$5:$W$168,$B14,Top!AK$5:AK$167)+SUMIF(Mid!$W$5:$W$168,$B14,Mid!AK$5:AK$167) -> 0 | Q14: =SUM(C14:P14) -> 46 | R14: =IF(Q14=0,0,Q14/COUNTIF(C14:P14,">0")) -> 46 | T14: 6 | U14: 36 | V14: 14 | W14: 3
B15: 40A-VIGO-COSTAS | C15: =SUMIF(Top!$W$5:$W$168,$B15,Top!X$5:X$167)+SUMIF(Mid!$W$5:$W$168,$B15,Mid!X$5:X$167) -> 46 | D15: =SUMIF(Top!$W$5:$W$168,$B15,Top!Y$5:Y$167)+SUMIF(Mid!$W$5:$W$168,$B15,Mid!Y$5:Y$167) -> 0 | E15: =SUMIF(Top!$W$5:$W$168,$B15,Top!Z$5:Z$167)+SUMIF(Mid!$W$5:$W$168,$B15,Mid!Z$5:Z$167) -> 26 | F15: =SUMIF(Top!$W$5:$W$168,$B15,Top!AA$5:AA$167)+SUMIF(Mid!$W$5:$W$168,$B15,Mid!AA$5:AA$167) -> 0 | G15: =SUMIF(Top!$W$5:$W$168,$B15,Top!AB$5:AB$167)+SUMIF(Mid!$W$5:$W$168,$B15,Mid!AB$5:AB$167) -> 0 | H15: =SUMIF(Top!$W$5:$W$168,$B15,Top!AC$5:AC$167)+SUMIF(Mid!$W$5:$W$168,$B15,Mid!AC$5:AC$167) -> 0 | I15: =SUMIF(Top!$W$5:$W$168,$B15,Top!AD$5:AD$167)+SUMIF(Mid!$W$5:$W$168,$B15,Mid!AD$5:AD$167) -> 0 | J15: =SUMIF(Top!$W$5:$W$168,$B15,Top!AE$5:AE$167)+SUMIF(Mid!$W$5:$W$168,$B15,Mid!AE$5:AE$167) -> 0 | ... P15: =SUMIF(Top!$W$5:$W$168,$B15,Top!AK$5:AK$167)+SUMIF(Mid!$W$5:$W$168,$B15,Mid!AK$5:AK$167) -> 0 | Q15: =SUM(C15:P15) -> 72 | R15: =IF(Q15=0,0,Q15/COUNTIF(C15:P15,">0")) -> 36 | T15: 7 | U15: 34 | V15: 12 | W15: 2
B16: 04B-NCME-KELL | C16: =SUMIF(Top!$W$5:$W$168,$B16,Top!X$5:X$167)+SUMIF(Mid!$W$5:$W$168,$B16,Mid!X$5:X$167) -> 0 | D16: =SUMIF(Top!$W$5:$W$168,$B16,Top!Y$5:Y$167)+SUMIF(Mid!$W$5:$W$168,$B16,Mid!Y$5:Y$167) -> 42 | E16: =SUMIF(Top!$W$5:$W$168,$B16,Top!Z$5:Z$167)+SUMIF(Mid!$W$5:$W$168,$B16,Mid!Z$5:Z$167) -> 0 | F16: =SUMIF(Top!$W$5:$W$168,$B16,Top!AA$5:AA$167)+SUMIF(Mid!$W$5:$W$168,$B16,Mid!AA$5:AA$167) -> 42 | G16: =SUMIF(Top!$W$5:$W$168,$B16,Top!AB$5:AB$167)+SUMIF(Mid!$W$5:$W$168,$B16,Mid!AB$5:AB$167) -> 0 | H16: =SUMIF(Top!$W$5:$W$168,$B16,Top!AC$5:AC$167)+SUMIF(Mid!$W$5:$W$168,$B16,Mid!AC$5:AC$167) -> 0 | I16: =SUMIF(Top!$W$5:$W$168,$B16,Top!AD$5:AD$167)+SUMIF(Mid!$W$5:$W$168,$B16,Mid!AD$5:AD$167) -> 0 | J16: =SUMIF(Top!$W$5:$W$168,$B16,Top!AE$5:AE$167)+SUMIF(Mid!$W$5:$W$168,$B16,Mid!AE$5:AE$167) -> 0 | ... P16: =SUMIF(Top!$W$5:$W$168,$B16,Top!AK$5:AK$167)+SUMIF(Mid!$W$5:$W$168,$B16,Mid!AK$5:AK$167) -> 0 | Q16: =SUM(C16:P16) -> 84 | R16: =IF(Q16=0,0,Q16/COUNTIF(C16:P16,">0")) -> 42 | T16: 8 | U16: 32 | V16: 10 | W16: 1
B17: 48A-UPRAF-DZIUBA | C17: =SUMIF(Top!$W$5:$W$168,$B17,Top!X$5:X$167)+SUMIF(Mid!$W$5:$W$168,$B17,Mid!X$5:X$167) -> 50 | D17: =SUMIF(Top!$W$5:$W$168,$B17,Top!Y$5:Y$167)+SUMIF(Mid!$W$5:$W$168,$B17,Mid!Y$5:Y$167) -> 0 | E17: =SUMIF(Top!$W$5:$W$168,$B17,Top!Z$5:Z$167)+SUMIF(Mid!$W$5:$W$168,$B17,Mid!Z$5:Z$167) -> 39 | F17: =SUMIF(Top!$W$5:$W$168,$B17,Top!AA$5:AA$167)+SUMIF(Mid!$W$5:$W$168,$B17,Mid!AA$5:AA$167) -> 32 | G17: =SUMIF(Top!$W$5:$W$168,$B17,Top!AB$5:AB$167)+SUMIF(Mid!$W$5:$W$168,$B17,Mid!AB$5:AB$167) -> 0 | H17: =SUMIF(Top!$W$5:$W$168,$B17,Top!AC$5:AC$167)+SUMIF(Mid!$W$5:$W$168,$B17,Mid!AC$5:AC$167) -> 0 | I17: =SUMIF(Top!$W$5:$W$168,$B17,Top!AD$5:AD$167)+SUMIF(Mid!$W$5:$W$168,$B17,Mid!AD$5:AD$167) -> 0 | J17: =SUMIF(Top!$W$5:$W$168,$B17,Top!AE$5:AE$167)+SUMIF(Mid!$W$5:$W$168,$B17,Mid!AE$5:AE$167) -> 0 | ... P17: =SUMIF(Top!$W$5:$W$168,$B17,Top!AK$5:AK$167)+SUMIF(Mid!$W$5:$W$168,$B17,Mid!AK$5:AK$167) -> 0 | Q17: =SUM(C17:P17) -> 121 | R17: =IF(Q17=0,0,Q17/COUNTIF(C17:P17,">0")) -> 40.333333 | T17: 9 | U17: 30 | V17: 8 | W17: 0
B18: 06A-SALF-WHEATER | C18: =SUMIF(Top!$W$5:$W$168,$B18,Top!X$5:X$167)+SUMIF(Mid!$W$5:$W$168,$B18,Mid!X$5:X$167) -> 42 | D18: =SUMIF(Top!$W$5:$W$168,$B18,Top!Y$5:Y$167)+SUMIF(Mid!$W$5:$W$168,$B18,Mid!Y$5:Y$167) -> 0 | E18: =SUMIF(Top!$W$5:$W$168,$B18,Top!Z$5:Z$167)+SUMIF(Mid!$W$5:$W$168,$B18,Mid!Z$5:Z$167) -> 36 | F18: =SUMIF(Top!$W$5:$W$168,$B18,Top!AA$5:AA$167)+SUMIF(Mid!$W$5:$W$168,$B18,Mid!AA$5:AA$167) -> 42 | G18: =SUMIF(Top!$W$5:$W$168,$B18,Top!AB$5:AB$167)+SUMIF(Mid!$W$5:$W$168,$B18,Mid!AB$5:AB$167) -> 0 | H18: =SUMIF(Top!$W$5:$W$168,$B18,Top!AC$5:AC$167)+SUMIF(Mid!$W$5:$W$168,$B18,Mid!AC$5:AC$167) -> 0 | I18: =SUMIF(Top!$W$5:$W$168,$B18,Top!AD$5:AD$167)+SUMIF(Mid!$W$5:$W$168,$B18,Mid!AD$5:AD$167) -> 0 | J18: =SUMIF(Top!$W$5:$W$168,$B18,Top!AE$5:AE$167)+SUMIF(Mid!$W$5:$W$168,$B18,Mid!AE$5:AE$167) -> 0 | ... P18: =SUMIF(Top!$W$5:$W$168,$B18,Top!AK$5:AK$167)+SUMIF(Mid!$W$5:$W$168,$B18,Mid!AK$5:AK$167) -> 0 | Q18: =SUM(C18:P18) -> 120 | R18: =IF(Q18=0,0,Q18/COUNTIF(C18:P18,">0")) -> 40 | T18: 10 | U18: 28 | V18: 6 | W18: 0
B19: 03A-HULLA-DAVISON | C19: =SUMIF(Top!$W$5:$W$168,$B19,Top!X$5:X$167)+SUMIF(Mid!$W$5:$W$168,$B19,Mid!X$5:X$167) -> 38 | D19: =SUMIF(Top!$W$5:$W$168,$B19,Top!Y$5:Y$167)+SUMIF(Mid!$W$5:$W$168,$B19,Mid!Y$5:Y$167) -> 0 | E19: =SUMIF(Top!$W$5:$W$168,$B19,Top!Z$5:Z$167)+SUMIF(Mid!$W$5:$W$168,$B19,Mid!Z$5:Z$167) -> 42 | F19: =SUMIF(Top!$W$5:$W$168,$B19,Top!AA$5:AA$167)+SUMIF(Mid!$W$5:$W$168,$B19,Mid!AA$5:AA$167) -> 0 | G19: =SUMIF(Top!$W$5:$W$168,$B19,Top!AB$5:AB$167)+SUMIF(Mid!$W$5:$W$168,$B19,Mid!AB$5:AB$167) -> 0 | H19: =SUMIF(Top!$W$5:$W$168,$B19,Top!AC$5:AC$167)+SUMIF(Mid!$W$5:$W$168,$B19,Mid!AC$5:AC$167) -> 0 | I19: =SUMIF(Top!$W$5:$W$168,$B19,Top!AD$5:AD$167)+SUMIF(Mid!$W$5:$W$168,$B19,Mid!AD$5:AD$167) -> 0 | J19: =SUMIF(Top!$W$5:$W$168,$B19,Top!AE$5:AE$167)+SUMIF(Mid!$W$5:$W$168,$B19,Mid!AE$5:AE$167) -> 0 | ... P19: =SUMIF(Top!$W$5:$W$168,$B19,Top!AK$5:AK$167)+SUMIF(Mid!$W$5:$W$168,$B19,Mid!AK$5:AK$167) -> 0 | Q19: =SUM(C19:P19) -> 80 | R19: =IF(Q19=0,0,Q19/COUNTIF(C19:P19,">0")) -> 40 | T19: 11 | U19: 26 | V19: 5 | W19: 0
B20: 05E-UWTSD-GRAY | C20: =SUMIF(Top!$W$5:$W$168,$B20,Top!X$5:X$167)+SUMIF(Mid!$W$5:$W$168,$B20,Mid!X$5:X$167) -> 0 | D20: =SUMIF(Top!$W$5:$W$168,$B20,Top!Y$5:Y$167)+SUMIF(Mid!$W$5:$W$168,$B20,Mid!Y$5:Y$167) -> 40 | E20: =SUMIF(Top!$W$5:$W$168,$B20,Top!Z$5:Z$167)+SUMIF(Mid!$W$5:$W$168,$B20,Mid!Z$5:Z$167) -> 0 | F20: =SUMIF(Top!$W$5:$W$168,$B20,Top!AA$5:AA$167)+SUMIF(Mid!$W$5:$W$168,$B20,Mid!AA$5:AA$167) -> 0 | G20: =SUMIF(Top!$W$5:$W$168,$B20,Top!AB$5:AB$167)+SUMIF(Mid!$W$5:$W$168,$B20,Mid!AB$5:AB$167) -> 0 | H20: =SUMIF(Top!$W$5:$W$168,$B20,Top!AC$5:AC$167)+SUMIF(Mid!$W$5:$W$168,$B20,Mid!AC$5:AC$167) -> 0 | I20: =SUMIF(Top!$W$5:$W$168,$B20,Top!AD$5:AD$167)+SUMIF(Mid!$W$5:$W$168,$B20,Mid!AD$5:AD$167) -> 0 | J20: =SUMIF(Top!$W$5:$W$168,$B20,Top!AE$5:AE$167)+SUMIF(Mid!$W$5:$W$168,$B20,Mid!AE$5:AE$167) -> 0 | ... P20: =SUMIF(Top!$W$5:$W$168,$B20,Top!AK$5:AK$167)+SUMIF(Mid!$W$5:$W$168,$B20,Mid!AK$5:AK$167) -> 0 | Q20: =SUM(C20:P20) -> 40 | R20: =IF(Q20=0,0,Q20/COUNTIF(C20:P20,">0")) -> 40 | T20: 12 | U20: 24 | V20: 4 | W20: 0
B21: 50C-LJMU-SCHAPENDONK | C21: =SUMIF(Top!$W$5:$W$168,$B21,Top!X$5:X$167)+SUMIF(Mid!$W$5:$W$168,$B21,Mid!X$5:X$167) -> 0 | D21: =SUMIF(Top!$W$5:$W$168,$B21,Top!Y$5:Y$167)+SUMIF(Mid!$W$5:$W$168,$B21,Mid!Y$5:Y$167) -> 0 | E21: =SUMIF(Top!$W$5:$W$168,$B21,Top!Z$5:Z$167)+SUMIF(Mid!$W$5:$W$168,$B21,Mid!Z$5:Z$167) -> 40 | F21: =SUMIF(Top!$W$5:$W$168,$B21,Top!AA$5:AA$167)+SUMIF(Mid!$W$5:$W$168,$B21,Mid!AA$5:AA$167) -> 0 | G21: =SUMIF(Top!$W$5:$W$168,$B21,Top!AB$5:AB$167)+SUMIF(Mid!$W$5:$W$168,$B21,Mid!AB$5:AB$167) -> 0 | H21: =SUMIF(Top!$W$5:$W$168,$B21,Top!AC$5:AC$167)+SUMIF(Mid!$W$5:$W$168,$B21,Mid!AC$5:AC$167) -> 0 | I21: =SUMIF(Top!$W$5:$W$168,$B21,Top!AD$5:AD$167)+SUMIF(Mid!$W$5:$W$168,$B21,Mid!AD$5:AD$167) -> 0 | J21: =SUMIF(Top!$W$5:$W$168,$B21,Top!AE$5:AE$167)+SUMIF(Mid!$W$5:$W$168,$B21,Mid!AE$5:AE$167) -> 0 | ... P21: =SUMIF(Top!$W$5:$W$168,$B21,Top!AK$5:AK$167)+SUMIF(Mid!$W$5:$W$168,$B21,Mid!AK$5:AK$167) -> 0 | Q21: =SUM(C21:P21) -> 40 | R21: =IF(Q21=0,0,Q21/COUNTIF(C21:P21,">0")) -> 40 | T21: 13 | U21: 22 | V21: 3 | W21: 0
B22: 43C-BATH-KHAN | C22: =SUMIF(Top!$W$5:$W$168,$B22,Top!X$5:X$167)+SUMIF(Mid!$W$5:$W$168,$B22,Mid!X$5:X$167) -> 0 | D22: =SUMIF(Top!$W$5:$W$168,$B22,Top!Y$5:Y$167)+SUMIF(Mid!$W$5:$W$168,$B22,Mid!Y$5:Y$167) -> 0 | E22: =SUMIF(Top!$W$5:$W$168,$B22,Top!Z$5:Z$167)+SUMIF(Mid!$W$5:$W$168,$B22,Mid!Z$5:Z$167) -> 0 | F22: =SUMIF(Top!$W$5:$W$168,$B22,Top!AA$5:AA$167)+SUMIF(Mid!$W$5:$W$168,$B22,Mid!AA$5:AA$167) -> 38 | G22: =SUMIF(Top!$W$5:$W$168,$B22,Top!AB$5:AB$167)+SUMIF(Mid!$W$5:$W$168,$B22,Mid!AB$5:AB$167) -> 0 | H22: =SUMIF(Top!$W$5:$W$168,$B22,Top!AC$5:AC$167)+SUMIF(Mid!$W$5:$W$168,$B22,Mid!AC$5:AC$167) -> 0 | I22: =SUMIF(Top!$W$5:$W$168,$B22,Top!AD$5:AD$167)+SUMIF(Mid!$W$5:$W$168,$B22,Mid!AD$5:AD$167) -> 0 | J22: =SUMIF(Top!$W$5:$W$168,$B22,Top!AE$5:AE$167)+SUMIF(Mid!$W$5:$W$168,$B22,Mid!AE$5:AE$167) -> 0 | ... P22: =SUMIF(Top!$W$5:$W$168,$B22,Top!AK$5:AK$167)+SUMIF(Mid!$W$5:$W$168,$B22,Mid!AK$5:AK$167) -> 0 | Q22: =SUM(C22:P22) -> 38 | R22: =IF(Q22=0,0,Q22/COUNTIF(C22:P22,">0")) -> 38 | T22: 14 | U22: 20 | V22: 2 | W22: 0
... B28: 04C-NCME-CAMPBELL | C28: =SUMIF(Top!$W$5:$W$168,$B28,Top!X$5:X$167)+SUMIF(Mid!$W$5:$W$168,$B28,Mid!X$5:X$167) -> 40 | D28: =SUMIF(Top!$W$5:$W$168,$B28,Top!Y$5:Y$167)+SUMIF(Mid!$W$5:$W$168,$B28,Mid!Y$5:Y$167) -> 0 | E28: =SUMIF(Top!$W$5:$W$168,$B28,Top!Z$5:Z$167)+SUMIF(Mid!$W$5:$W$168,$B28,Mid!Z$5:Z$167) -> 22 | F28: =SUMIF(Top!$W$5:$W$168,$B28,Top!AA$5:AA$167)+SUMIF(Mid!$W$5:$W$168,$B28,Mid!AA$5:AA$167) -> 0 | G28: =SUMIF(Top!$W$5:$W$168,$B28,Top!AB$5:AB$167)+SUMIF(Mid!$W$5:$W$168,$B28,Mid!AB$5:AB$167) -> 0 | H28: =SUMIF(Top!$W$5:$W$168,$B28,Top!AC$5:AC$167)+SUMIF(Mid!$W$5:$W$168,$B28,Mid!AC$5:AC$167) -> 0 | I28: =SUMIF(Top!$W$5:$W$168,$B28,Top!AD$5:AD$167)+SUMIF(Mid!$W$5:$W$168,$B28,Mid!AD$5:AD$167) -> 0 | J28: =SUMIF(Top!$W$5:$W$168,$B28,Top!AE$5:AE$167)+SUMIF(Mid!$W$5:$W$168,$B28,Mid!AE$5:AE$167) -> 0 | ... P28: =SUMIF(Top!$W$5:$W$168,$B28,Top!AK$5:AK$167)+SUMIF(Mid!$W$5:$W$168,$B28,Mid!AK$5:AK$167) -> 0 | Q28: =SUM(C28:P28) -> 62 | R28: =IF(Q28=0,0,Q28/COUNTIF(C28:P28,">0")) -> 31 | T28: 20 | U28: 14 | V28: 0 | W28: 0
B29: 09D-VIT-MEDIAVILLA | C29: =SUMIF(Top!$W$5:$W$168,$B29,Top!X$5:X$167)+SUMIF(Mid!$W$5:$W$168,$B29,Mid!X$5:X$167) -> 8 | D29: =SUMIF(Top!$W$5:$W$168,$B29,Top!Y$5:Y$167)+SUMIF(Mid!$W$5:$W$168,$B29,Mid!Y$5:Y$167) -> 0 | E29: =SUMIF(Top!$W$5:$W$168,$B29,Top!Z$5:Z$167)+SUMIF(Mid!$W$5:$W$168,$B29,Mid!Z$5:Z$167) -> 30 | F29: =SUMIF(Top!$W$5:$W$168,$B29,Top!AA$5:AA$167)+SUMIF(Mid!$W$5:$W$168,$B29,Mid!AA$5:AA$167) -> 0 | G29: =SUMIF(Top!$W$5:$W$168,$B29,Top!AB$5:AB$167)+SUMIF(Mid!$W$5:$W$168,$B29,Mid!AB$5:AB$167) -> 0 | H29: =SUMIF(Top!$W$5:$W$168,$B29,Top!AC$5:AC$167)+SUMIF(Mid!$W$5:$W$168,$B29,Mid!AC$5:AC$167) -> 0 | I29: =SUMIF(Top!$W$5:$W$168,$B29,Top!AD$5:AD$167)+SUMIF(Mid!$W$5:$W$168,$B29,Mid!AD$5:AD$167) -> 0 | J29: =SUMIF(Top!$W$5:$W$168,$B29,Top!AE$5:AE$167)+SUMIF(Mid!$W$5:$W$168,$B29,Mid!AE$5:AE$167) -> 0 | ... P29: =SUMIF(Top!$W$5:$W$168,$B29,Top!AK$5:AK$167)+SUMIF(Mid!$W$5:$W$168,$B29,Mid!AK$5:AK$167) -> 0 | Q29: =SUM(C29:P29) -> 38 | R29: =IF(Q29=0,0,Q29/COUNTIF(C29:P29,">0")) -> 19
B30: 50A-LJMU-MELLIAR-SMITH | C30: =SUMIF(Top!$W$5:$W$168,$B30,Top!X$5:X$167)+SUMIF(Mid!$W$5:$W$168,$B30,Mid!X$5:X$167) -> 0 | D30: =SUMIF(Top!$W$5:$W$168,$B30,Top!Y$5:Y$167)+SUMIF(Mid!$W$5:$W$168,$B30,Mid!Y$5:Y$167) -> 0 | E30: =SUMIF(Top!$W$5:$W$168,$B30,Top!Z$5:Z$167)+SUMIF(Mid!$W$5:$W$168,$B30,Mid!Z$5:Z$167) -> 0 | F30: =SUMIF(Top!$W$5:$W$168,$B30,Top!AA$5:AA$167)+SUMIF(Mid!$W$5:$W$168,$B30,Mid!AA$5:AA$167) -> 30 | G30: =SUMIF(Top!$W$5:$W$168,$B30,Top!AB$5:AB$167)+SUMIF(Mid!$W$5:$W$168,$B30,Mid!AB$5:AB$167) -> 0 | H30: =SUMIF(Top!$W$5:$W$168,$B30,Top!AC$5:AC$167)+SUMIF(Mid!$W$5:$W$168,$B30,Mid!AC$5:AC$167) -> 0 | I30: =SUMIF(Top!$W$5:$W$168,$B30,Top!AD$5:AD$167)+SUMIF(Mid!$W$5:$W$168,$B30,Mid!AD$5:AD$167) -> 0 | J30: =SUMIF(Top!$W$5:$W$168,$B30,Top!AE$5:AE$167)+SUMIF(Mid!$W$5:$W$168,$B30,Mid!AE$5:AE$167) -> 0 | ... P30: =SUMIF(Top!$W$5:$W$168,$B30,Top!AK$5:AK$167)+SUMIF(Mid!$W$5:$W$168,$B30,Mid!AK$5:AK$167) -> 0 | Q30: =SUM(C30:P30) -> 30 | R30: =IF(Q30=0,0,Q30/COUNTIF(C30:P30,">0")) -> 30
B31: 03B-HULLA-PHILIP | C31: =SUMIF(Top!$W$5:$W$168,$B31,Top!X$5:X$167)+SUMIF(Mid!$W$5:$W$168,$B31,Mid!X$5:X$167) -> 0 | D31: =SUMIF(Top!$W$5:$W$168,$B31,Top!Y$5:Y$167)+SUMIF(Mid!$W$5:$W$168,$B31,Mid!Y$5:Y$167) -> 36 | E31: =SUMIF(Top!$W$5:$W$168,$B31,Top!Z$5:Z$167)+SUMIF(Mid!$W$5:$W$168,$B31,Mid!Z$5:Z$167) -> 0 | F31: =SUMIF(Top!$W$5:$W$168,$B31,Top!AA$5:AA$167)+SUMIF(Mid!$W$5:$W$168,$B31,Mid!AA$5:AA$167) -> 22 | G31: =SUMIF(Top!$W$5:$W$168,$B31,Top!AB$5:AB$167)+SUMIF(Mid!$W$5:$W$168,$B31,Mid!AB$5:AB$167) -> 0 | H31: =SUMIF(Top!$W$5:$W$168,$B31,Top!AC$5:AC$167)+SUMIF(Mid!$W$5:$W$168,$B31,Mid!AC$5:AC$167) -> 0 | I31: =SUMIF(Top!$W$5:$W$168,$B31,Top!AD$5:AD$167)+SUMIF(Mid!$W$5:$W$168,$B31,Mid!AD$5:AD$167) -> 0 | J31: =SUMIF(Top!$W$5:$W$168,$B31,Top!AE$5:AE$167)+SUMIF(Mid!$W$5:$W$168,$B31,Mid!AE$5:AE$167) -> 0 | ... P31: =SUMIF(Top!$W$5:$W$168,$B31,Top!AK$5:AK$167)+SUMIF(Mid!$W$5:$W$168,$B31,Mid!AK$5:AK$167) -> 0 | Q31: =SUM(C31:P31) -> 58 | R31: =IF(Q31=0,0,Q31/COUNTIF(C31:P31,">0")) -> 29
B32: 35A-UCD-GARRETT | C32: =SUMIF(Top!$W$5:$W$168,$B32,Top!X$5:X$167)+SUMIF(Mid!$W$5:$W$168,$B32,Mid!X$5:X$167) -> 29 | D32: =SUMIF(Top!$W$5:$W$168,$B32,Top!Y$5:Y$167)+SUMIF(Mid!$W$5:$W$168,$B32,Mid!Y$5:Y$167) -> 0 | E32: =SUMIF(Top!$W$5:$W$168,$B32,Top!Z$5:Z$167)+SUMIF(Mid!$W$5:$W$168,$B32,Mid!Z$5:Z$167) -> 0 | F32: =SUMIF(Top!$W$5:$W$168,$B32,Top!AA$5:AA$167)+SUMIF(Mid!$W$5:$W$168,$B32,Mid!AA$5:AA$167) -> 28 | G32: =SUMIF(Top!$W$5:$W$168,$B32,Top!AB$5:AB$167)+SUMIF(Mid!$W$5:$W$168,$B32,Mid!AB$5:AB$167) -> 0 | H32: =SUMIF(Top!$W$5:$W$168,$B32,Top!AC$5:AC$167)+SUMIF(Mid!$W$5:$W$168,$B32,Mid!AC$5:AC$167) -> 0 | I32: =SUMIF(Top!$W$5:$W$168,$B32,Top!AD$5:AD$167)+SUMIF(Mid!$W$5:$W$168,$B32,Mid!AD$5:AD$167) -> 0 | J32: =SUMIF(Top!$W$5:$W$168,$B32,Top!AE$5:AE$167)+SUMIF(Mid!$W$5:$W$168,$B32,Mid!AE$5:AE$167) -> 0 | ... P32: =SUMIF(Top!$W$5:$W$168,$B32,Top!AK$5:AK$167)+SUMIF(Mid!$W$5:$W$168,$B32,Mid!AK$5:AK$167) -> 0 | Q32: =SUM(C32:P32) -> 57 | R32: =IF(Q32=0,0,Q32/COUNTIF(C32:P32,">0")) -> 28.5
B33: 51A-QMFS-ALOJ | C33: =SUMIF(Top!$W$5:$W$168,$B33,Top!X$5:X$167)+SUMIF(Mid!$W$5:$W$168,$B33,Mid!X$5:X$167) -> 0 | D33: =SUMIF(Top!$W$5:$W$168,$B33,Top!Y$5:Y$167)+SUMIF(Mid!$W$5:$W$168,$B33,Mid!Y$5:Y$167) -> 38 | E33: =SUMIF(Top!$W$5:$W$168,$B33,Top!Z$5:Z$167)+SUMIF(Mid!$W$5:$W$168,$B33,Mid!Z$5:Z$167) -> 0 | F33: =SUMIF(Top!$W$5:$W$168,$B33,Top!AA$5:AA$167)+SUMIF(Mid!$W$5:$W$168,$B33,Mid!AA$5:AA$167) -> 18 | G33: =SUMIF(Top!$W$5:$W$168,$B33,Top!AB$5:AB$167)+SUMIF(Mid!$W$5:$W$168,$B33,Mid!AB$5:AB$167) -> 0 | H33: =SUMIF(Top!$W$5:$W$168,$B33,Top!AC$5:AC$167)+SUMIF(Mid!$W$5:$W$168,$B33,Mid!AC$5:AC$167) -> 0 | I33: =SUMIF(Top!$W$5:$W$168,$B33,Top!AD$5:AD$167)+SUMIF(Mid!$W$5:$W$168,$B33,Mid!AD$5:AD$167) -> 0 | J33: =SUMIF(Top!$W$5:$W$168,$B33,Top!AE$5:AE$167)+SUMIF(Mid!$W$5:$W$168,$B33,Mid!AE$5:AE$167) -> 0 | ... P33: =SUMIF(Top!$W$5:$W$168,$B33,Top!AK$5:AK$167)+SUMIF(Mid!$W$5:$W$168,$B33,Mid!AK$5:AK$167) -> 0 | Q33: =SUM(C33:P33) -> 56 | R33: =IF(Q33=0,0,Q33/COUNTIF(C33:P33,">0")) -> 28
B34: 38C-EXET-PRITCHARD | C34: =SUMIF(Top!$W$5:$W$168,$B34,Top!X$5:X$167)+SUMIF(Mid!$W$5:$W$168,$B34,Mid!X$5:X$167) -> 36 | D34: =SUMIF(Top!$W$5:$W$168,$B34,Top!Y$5:Y$167)+SUMIF(Mid!$W$5:$W$168,$B34,Mid!Y$5:Y$167) -> 0 | E34: =SUMIF(Top!$W$5:$W$168,$B34,Top!Z$5:Z$167)+SUMIF(Mid!$W$5:$W$168,$B34,Mid!Z$5:Z$167) -> 20 | F34: =SUMIF(Top!$W$5:$W$168,$B34,Top!AA$5:AA$167)+SUMIF(Mid!$W$5:$W$168,$B34,Mid!AA$5:AA$167) -> 24 | G34: =SUMIF(Top!$W$5:$W$168,$B34,Top!AB$5:AB$167)+SUMIF(Mid!$W$5:$W$168,$B34,Mid!AB$5:AB$167) -> 0 | H34: =SUMIF(Top!$W$5:$W$168,$B34,Top!AC$5:AC$167)+SUMIF(Mid!$W$5:$W$168,$B34,Mid!AC$5:AC$167) -> 0 | I34: =SUMIF(Top!$W$5:$W$168,$B34,Top!AD$5:AD$167)+SUMIF(Mid!$W$5:$W$168,$B34,Mid!AD$5:AD$167) -> 0 | J34: =SUMIF(Top!$W$5:$W$168,$B34,Top!AE$5:AE$167)+SUMIF(Mid!$W$5:$W$168,$B34,Mid!AE$5:AE$167) -> 0 | ... P34: =SUMIF(Top!$W$5:$W$168,$B34,Top!AK$5:AK$167)+SUMIF(Mid!$W$5:$W$168,$B34,Mid!AK$5:AK$167) -> 0 | Q34: =SUM(C34:P34) -> 80 | R34: =IF(Q34=0,0,Q34/COUNTIF(C34:P34,">0")) -> 26.666667
B35: 23A-HULLB-ZALESKI | C35: =SUMIF(Top!$W$5:$W$168,$B35,Top!X$5:X$167)+SUMIF(Mid!$W$5:$W$168,$B35,Mid!X$5:X$167) -> 33 | D35: =SUMIF(Top!$W$5:$W$168,$B35,Top!Y$5:Y$167)+SUMIF(Mid!$W$5:$W$168,$B35,Mid!Y$5:Y$167) -> 31 | E35: =SUMIF(Top!$W$5:$W$168,$B35,Top!Z$5:Z$167)+SUMIF(Mid!$W$5:$W$168,$B35,Mid!Z$5:Z$167) -> 15 | F35: =SUMIF(Top!$W$5:$W$168,$B35,Top!AA$5:AA$167)+SUMIF(Mid!$W$5:$W$168,$B35,Mid!AA$5:AA$167) -> 0 | G35: =SUMIF(Top!$W$5:$W$168,$B35,Top!AB$5:AB$167)+SUMIF(Mid!$W$5:$W$168,$B35,Mid!AB$5:AB$167) -> 0 | H35: =SUMIF(Top!$W$5:$W$168,$B35,Top!AC$5:AC$167)+SUMIF(Mid!$W$5:$W$168,$B35,Mid!AC$5:AC$167) -> 0 | I35: =SUMIF(Top!$W$5:$W$168,$B35,Top!AD$5:AD$167)+SUMIF(Mid!$W$5:$W$168,$B35,Mid!AD$5:AD$167) -> 0 | J35: =SUMIF(Top!$W$5:$W$168,$B35,Top!AE$5:AE$167)+SUMIF(Mid!$W$5:$W$168,$B35,Mid!AE$5:AE$167) -> 0 | ... P35: =SUMIF(Top!$W$5:$W$168,$B35,Top!AK$5:AK$167)+SUMIF(Mid!$W$5:$W$168,$B35,Mid!AK$5:AK$167) -> 0 | Q35: =SUM(C35:P35) -> 79 | R35: =IF(Q35=0,0,Q35/COUNTIF(C35:P35,">0")) -> 26.333333
B36: 43A-BATH-DOORGEEST | C36: =SUMIF(Top!$W$5:$W$168,$B36,Top!X$5:X$167)+SUMIF(Mid!$W$5:$W$168,$B36,Mid!X$5:X$167) -> 26 | D36: =SUMIF(Top!$W$5:$W$168,$B36,Top!Y$5:Y$167)+SUMIF(Mid!$W$5:$W$168,$B36,Mid!Y$5:Y$167) -> 0 | E36: =SUMIF(Top!$W$5:$W$168,$B36,Top!Z$5:Z$167)+SUMIF(Mid!$W$5:$W$168,$B36,Mid!Z$5:Z$167) -> 26 | F36: =SUMIF(Top!$W$5:$W$168,$B36,Top!AA$5:AA$167)+SUMIF(Mid!$W$5:$W$168,$B36,Mid!AA$5:AA$167) -> 0 | G36: =SUMIF(Top!$W$5:$W$168,$B36,Top!AB$5:AB$167)+SUMIF(Mid!$W$5:$W$168,$B36,Mid!AB$5:AB$167) -> 0 | H36: =SUMIF(Top!$W$5:$W$168,$B36,Top!AC$5:AC$167)+SUMIF(Mid!$W$5:$W$168,$B36,Mid!AC$5:AC$167) -> 0 | I36: =SUMIF(Top!$W$5:$W$168,$B36,Top!AD$5:AD$167)+SUMIF(Mid!$W$5:$W$168,$B36,Mid!AD$5:AD$167) -> 0 | J36: =SUMIF(Top!$W$5:$W$168,$B36,Top!AE$5:AE$167)+SUMIF(Mid!$W$5:$W$168,$B36,Mid!AE$5:AE$167) -> 0 | ... P36: =SUMIF(Top!$W$5:$W$168,$B36,Top!AK$5:AK$167)+SUMIF(Mid!$W$5:$W$168,$B36,Mid!AK$5:AK$167) -> 0 | Q36: =SUM(C36:P36) -> 52 | R36: =IF(Q36=0,0,Q36/COUNTIF(C36:P36,">0")) -> 26
B37: 37A-POLYU-LAM | C37: =SUMIF(Top!$W$5:$W$168,$B37,Top!X$5:X$167)+SUMIF(Mid!$W$5:$W$168,$B37,Mid!X$5:X$167) -> 17 | D37: =SUMIF(Top!$W$5:$W$168,$B37,Top!Y$5:Y$167)+SUMIF(Mid!$W$5:$W$168,$B37,Mid!Y$5:Y$167) -> 0 | E37: =SUMIF(Top!$W$5:$W$168,$B37,Top!Z$5:Z$167)+SUMIF(Mid!$W$5:$W$168,$B37,Mid!Z$5:Z$167) -> 0 | F37: =SUMIF(Top!$W$5:$W$168,$B37,Top!AA$5:AA$167)+SUMIF(Mid!$W$5:$W$168,$B37,Mid!AA$5:AA$167) -> 34 | G37: =SUMIF(Top!$W$5:$W$168,$B37,Top!AB$5:AB$167)+SUMIF(Mid!$W$5:$W$168,$B37,Mid!AB$5:AB$167) -> 0 | H37: =SUMIF(Top!$W$5:$W$168,$B37,Top!AC$5:AC$167)+SUMIF(Mid!$W$5:$W$168,$B37,Mid!AC$5:AC$167) -> 0 | I37: =SUMIF(Top!$W$5:$W$168,$B37,Top!AD$5:AD$167)+SUMIF(Mid!$W$5:$W$168,$B37,Mid!AD$5:AD$167) -> 0 | J37: =SUMIF(Top!$W$5:$W$168,$B37,Top!AE$5:AE$167)+SUMIF(Mid!$W$5:$W$168,$B37,Mid!AE$5:AE$167) -> 0 | ... P37: =SUMIF(Top!$W$5:$W$168,$B37,Top!AK$5:AK$167)+SUMIF(Mid!$W$5:$W$168,$B37,Mid!AK$5:AK$167) -> 0 | Q37: =SUM(C37:P37) -> 51 | R37: =IF(Q37=0,0,Q37/COUNTIF(C37:P37,">0")) -> 25.5
B38: 21A-STAF-YOUDALE | C38: =SUMIF(Top!$W$5:$W$168,$B38,Top!X$5:X$167)+SUMIF(Mid!$W$5:$W$168,$B38,Mid!X$5:X$167) -> 22 | D38: =SUMIF(Top!$W$5:$W$168,$B38,Top!Y$5:Y$167)+SUMIF(Mid!$W$5:$W$168,$B38,Mid!Y$5:Y$167) -> 0 | E38: =SUMIF(Top!$W$5:$W$168,$B38,Top!Z$5:Z$167)+SUMIF(Mid!$W$5:$W$168,$B38,Mid!Z$5:Z$167) -> 28 | F38: =SUMIF(Top!$W$5:$W$168,$B38,Top!AA$5:AA$167)+SUMIF(Mid!$W$5:$W$168,$B38,Mid!AA$5:AA$167) -> 0 | G38: =SUMIF(Top!$W$5:$W$168,$B38,Top!AB$5:AB$167)+SUMIF(Mid!$W$5:$W$168,$B38,Mid!AB$5:AB$167) -> 0 | H38: =SUMIF(Top!$W$5:$W$168,$B38,Top!AC$5:AC$167)+SUMIF(Mid!$W$5:$W$168,$B38,Mid!AC$5:AC$167) -> 0 | I38: =SUMIF(Top!$W$5:$W$168,$B38,Top!AD$5:AD$167)+SUMIF(Mid!$W$5:$W$168,$B38,Mid!AD$5:AD$167) -> 0 | J38: =SUMIF(Top!$W$5:$W$168,$B38,Top!AE$5:AE$167)+SUMIF(Mid!$W$5:$W$168,$B38,Mid!AE$5:AE$167) -> 0 | ... P38: =SUMIF(Top!$W$5:$W$168,$B38,Top!AK$5:AK$167)+SUMIF(Mid!$W$5:$W$168,$B38,Mid!AK$5:AK$167) -> 0 | Q38: =SUM(C38:P38) -> 50 | R38: =IF(Q38=0,0,Q38/COUNTIF(C38:P38,">0")) -> 25
B39: 05A-UWTSD-GREENHILL-UPWARD | C39: =SUMIF(Top!$W$5:$W$168,$B39,Top!X$5:X$167)+SUMIF(Mid!$W$5:$W$168,$B39,Mid!X$5:X$167) -> 16 | D39: =SUMIF(Top!$W$5:$W$168,$B39,Top!Y$5:Y$167)+SUMIF(Mid!$W$5:$W$168,$B39,Mid!Y$5:Y$167) -> 0 | E39: =SUMIF(Top!$W$5:$W$168,$B39,Top!Z$5:Z$167)+SUMIF(Mid!$W$5:$W$168,$B39,Mid!Z$5:Z$167) -> 24 | F39: =SUMIF(Top!$W$5:$W$168,$B39,Top!AA$5:AA$167)+SUMIF(Mid!$W$5:$W$168,$B39,Mid!AA$5:AA$167) -> 0 | G39: =SUMIF(Top!$W$5:$W$168,$B39,Top!AB$5:AB$167)+SUMIF(Mid!$W$5:$W$168,$B39,Mid!AB$5:AB$167) -> 0 | H39: =SUMIF(Top!$W$5:$W$168,$B39,Top!AC$5:AC$167)+SUMIF(Mid!$W$5:$W$168,$B39,Mid!AC$5:AC$167) -> 0 | I39: =SUMIF(Top!$W$5:$W$168,$B39,Top!AD$5:AD$167)+SUMIF(Mid!$W$5:$W$168,$B39,Mid!AD$5:AD$167) -> 0 | J39: =SUMIF(Top!$W$5:$W$168,$B39,Top!AE$5:AE$167)+SUMIF(Mid!$W$5:$W$168,$B39,Mid!AE$5:AE$167) -> 0 | ... P39: =SUMIF(Top!$W$5:$W$168,$B39,Top!AK$5:AK$167)+SUMIF(Mid!$W$5:$W$168,$B39,Mid!AK$5:AK$167) -> 0 | Q39: =SUM(C39:P39) -> 40 | R39: =IF(Q39=0,0,Q39/COUNTIF(C39:P39,">0")) -> 20
B40: 24B-UPRE-DARVILL | C40: =SUMIF(Top!$W$5:$W$168,$B40,Top!X$5:X$167)+SUMIF(Mid!$W$5:$W$168,$B40,Mid!X$5:X$167) -> 24 | D40: =SUMIF(Top!$W$5:$W$168,$B40,Top!Y$5:Y$167)+SUMIF(Mid!$W$5:$W$168,$B40,Mid!Y$5:Y$167) -> 0 | E40: =SUMIF(Top!$W$5:$W$168,$B40,Top!Z$5:Z$167)+SUMIF(Mid!$W$5:$W$168,$B40,Mid!Z$5:Z$167) -> 0 | F40: =SUMIF(Top!$W$5:$W$168,$B40,Top!AA$5:AA$167)+SUMIF(Mid!$W$5:$W$168,$B40,Mid!AA$5:AA$167) -> 0 | G40: =SUMIF(Top!$W$5:$W$168,$B40,Top!AB$5:AB$167)+SUMIF(Mid!$W$5:$W$168,$B40,Mid!AB$5:AB$167) -> 0 | H40: =SUMIF(Top!$W$5:$W$168,$B40,Top!AC$5:AC$167)+SUMIF(Mid!$W$5:$W$168,$B40,Mid!AC$5:AC$167) -> 0 | I40: =SUMIF(Top!$W$5:$W$168,$B40,Top!AD$5:AD$167)+SUMIF(Mid!$W$5:$W$168,$B40,Mid!AD$5:AD$167) -> 0 | J40: =SUMIF(Top!$W$5:$W$168,$B40,Top!AE$5:AE$167)+SUMIF(Mid!$W$5:$W$168,$B40,Mid!AE$5:AE$167) -> 0 | ... P40: =SUMIF(Top!$W$5:$W$168,$B40,Top!AK$5:AK$167)+SUMIF(Mid!$W$5:$W$168,$B40,Mid!AK$5:AK$167) -> 0 | Q40: =SUM(C40:P40) -> 24 | R40: =IF(Q40=0,0,Q40/COUNTIF(C40:P40,">0")) -> 24
... B222: 53H-PROT-PISZCZEK | C222: =SUMIF(Top!$W$5:$W$168,$B222,Top!X$5:X$167)+SUMIF(Mid!$W$5:$W$168,$B222,Mid!X$5:X$167) -> 0 | D222: =SUMIF(Top!$W$5:$W$168,$B222,Top!Y$5:Y$167)+SUMIF(Mid!$W$5:$W$168,$B222,Mid!Y$5:Y$167) -> 0 | E222: =SUMIF(Top!$W$5:$W$168,$B222,Top!Z$5:Z$167)+SUMIF(Mid!$W$5:$W$168,$B222,Mid!Z$5:Z$167) -> 0 | F222: =SUMIF(Top!$W$5:$W$168,$B222,Top!AA$5:AA$167)+SUMIF(Mid!$W$5:$W$168,$B222,Mid!AA$5:AA$167) -> 0 | G222: =SUMIF(Top!$W$5:$W$168,$B222,Top!AB$5:AB$167)+SUMIF(Mid!$W$5:$W$168,$B222,Mid!AB$5:AB$167) -> 0 | H222: =SUMIF(Top!$W$5:$W$168,$B222,Top!AC$5:AC$167)+SUMIF(Mid!$W$5:$W$168,$B222,Mid!AC$5:AC$167) -> 0 | I222: =SUMIF(Top!$W$5:$W$168,$B222,Top!AD$5:AD$167)+SUMIF(Mid!$W$5:$W$168,$B222,Mid!AD$5:AD$167) -> 0 | J222: =SUMIF(Top!$W$5:$W$168,$B222,Top!AE$5:AE$167)+SUMIF(Mid!$W$5:$W$168,$B222,Mid!AE$5:AE$167) -> 0 | ... P222: =SUMIF(Top!$W$5:$W$168,$B222,Top!AK$5:AK$167)+SUMIF(Mid!$W$5:$W$168,$B222,Mid!AK$5:AK$167) -> 0 | Q222: =SUM(C222:P222) -> 0 | R222: =IF(Q222=0,0,Q222/COUNTIF(C222:P222,">0")) -> 0

Sheet Constructors
A1: TOTAL POINTS | D1: ROUND1 | G1: ROUND2 | I1: ROUND3 | L1: ROUND4 | O1: ROUND5 | R1: ROUND6 | U1: ROUND7
A2: {=_xlfn._xlws.SORT(AK2:BG55, 23,-1, FALSE)} -> Team Name | B2: Abrv | C2: No. | D2: R1A | E2: R1B | F2: EC1 | G2: R2A | H2: R2B | I2: R3A | J2: R3B | K2: EC2 | L2: R4A | M2: R4B | N2: EC3 | O2: R5A | P2: R5B | Q2: EC4 | R2: R6A | S2: R6B | T2: EC5 | U2: R7A | V2: R7B | W2: Total | AK2: Team Name | AL2: Abrv | AM2: No. | AN2: R1A | AO2: R1B | AP2: EC1 | AQ2: R2A | AR2: R2B | AS2: R3A | AT2: R3B | AU2: EC2 | AV2: R4A | AW2: R4B | AX2: EC3 | AY2: R5A | AZ2: R5B | BA2: EC4 | BB2: R6A | BC2: R6B | BD2: EC5 | BE2: R7A | BF2: R7B | BG2: Total
A3: SUFST | B3: STON | C3: 2 | D3: 16 | E3: 47 | F3: 45 | G3: 46 | H3: 51 | I3: 0 | J3: 0 | K3: 0 | L3: 0 | M3: 0 | N3: 0 | O3: 0 | P3: 0 | Q3: 0 | R3: 0 | S3: 0 | T3: 0 | U3: 0 | V3: 0 | W3: 205 | X3: =B3 -> STON | Y3: 1 | AK3: UG Racing | AL3: UGRA | AM3: 1 | AN3: =SUMIF(Drivers!$B$11:$B$222,"*-"&Constructors!$AL3&"-*",Drivers!C$11:C$222) -> 18 | AO3: =SUMIF(Drivers!$B$11:$B$222,"*-"&Constructors!$AL3&"-*",Drivers!D$11:D$222) -> 18 | AP3: 50 | AQ3: =SUMIF(Drivers!$B$11:$B$222,"*-"&Constructors!$AL3&"-*",Drivers!E$11:E$222) -> 51 | AR3: =SUMIF(Drivers!$B$11:$B$222,"*-"&Constructors!$AL3&"-*",Drivers!F$11:F$222) -> 45 | AS3: =SUMIF(Drivers!$B$11:$B$222,"*-"&Constructors!$AL3&"-*",Drivers!G$11:G$222) -> 0 | AT3: =SUMIF(Drivers!$B$11:$B$222,"*-"&Constructors!$AL3&"-*",Drivers!H$11:H$222) -> 0 | AV3: =SUMIF(Drivers!$B$11:$B$222,"*-"&Constructors!$AL3&"-*",Drivers!I$11:I$222) -> 0 | AW3: =SUMIF(Drivers!$B$11:$B$222,"*-"&Constructors!$AL3&"-*",Drivers!J$11:J$222) -> 0 | AY3: =SUMIF(Drivers!$B$11:$B$222,"*-"&Constructors!$AL3&"-*",Drivers!K$11:K$222) -> 0 | AZ3: =SUMIF(Drivers!$B$11:$B$222,"*-"&Constructors!$AL3&"-*",Drivers!L$11:L$222) -> 0 | BB3: =SUMIF(Drivers!$B$11:$B$222,"*-"&Constructors!$AL3&"-*",Drivers!M$11:M$222) -> 0 | BC3: =SUMIF(Drivers!$B$11:$B$222,"*-"&Constructors!$AL3&"-*",Drivers!N$11:N$222) -> 0 | BE3: =SUMIF(Drivers!$B$11:$B$222,"*-"&Constructors!$AL3&"-*",Drivers!O$11:O$222) -> 0 | BF3: =SUMIF(Drivers!$B$11:$B$222,"*-"&Constructors!$AL3&"-*",Drivers!P$11:P$222) -> 0 | BG3: =SUM(AN3:BF3) -> 182
A4: NCME Racing | B4: NCME | C4: 4 | D4: 40 | E4: 42 | F4: 42 | G4: 22 | H4: 42 | I4: 0 | J4: 0 | K4: 0 | L4: 0 | M4: 0 | N4: 0 | O4: 0 | P4: 0 | Q4: 0 | R4: 0 | S4: 0 | T4: 0 | U4: 0 | V4: 0 | W4: 188 | X4: =B4 -> NCME | Y4: 2 | Z4: -1 | AK4: SUFST | AL4: STON | AM4: 2 | AN4: =SUMIF(Drivers!$B$11:$B$222,"*-"&Constructors!$AL4&"-*",Drivers!C$11:C$222) -> 16 | AO4: =SUMIF(Drivers!$B$11:$B$222,"*-"&Constructors!$AL4&"-*",Drivers!D$11:D$222) -> 47 | AP4: 45 | AQ4: =SUMIF(Drivers!$B$11:$B$222,"*-"&Constructors!$AL4&"-*",Drivers!E$11:E$222) -> 46 | AR4: =SUMIF(Drivers!$B$11:$B$222,"*-"&Constructors!$AL4&"-*",Drivers!F$11:F$222) -> 51 | AS4: =SUMIF(Drivers!$B$11:$B$222,"*-"&Constructors!$AL4&"-*",Drivers!G$11:G$222) -> 0 | AT4: =SUMIF(Drivers!$B$11:$B$222,"*-"&Constructors!$AL4&"-*",Drivers!H$11:H$222) -> 0 | AV4: =SUMIF(Drivers!$B$11:$B$222,"*-"&Constructors!$AL4&"-*",Drivers!I$11:I$222) -> 0 | AW4: =SUMIF(Drivers!$B$11:$B$222,"*-"&Constructors!$AL4&"-*",Drivers!J$11:J$222) -> 0 | AY4: =SUMIF(Drivers!$B$11:$B$222,"*-"&Constructors!$AL4&"-*",Drivers!K$11:K$222) -> 0 | AZ4: =SUMIF(Drivers!$B$11:$B$222,"*-"&Constructors!$AL4&"-*",Drivers!L$11:L$222) -> 0 | BB4: =SUMIF(Drivers!$B$11:$B$222,"*-"&Constructors!$AL4&"-*",Drivers!M$11:M$222) -> 0 | BC4: =SUMIF(Drivers!$B$11:$B$222,"*-"&Constructors!$AL4&"-*",Drivers!N$11:N$222) -> 0 | BE4: =SUMIF(Drivers!$B$11:$B$222,"*-"&Constructors!$AL4&"-*",Drivers!O$11:O$222) -> 0 | BF4: =SUMIF(Drivers!$B$11:$B$222,"*-"&Constructors!$AL4&"-*",Drivers!P$11:P$222) -> 0 | BG4: =SUM(AN4:BF4) -> 205
A5: UG Racing | B5: UGRA | C5: 1 | D5: 18 | E5: 18 | F5: 50 | G5: 51 | H5: 45 | I5: 0 | J5: 0 | K5: 0 | L5: 0 | M5: 0 | N5: 0 | O5: 0 | P5: 0 | Q5: 0 | R5: 0 | S5: 0 | T5: 0 | U5: 0 | V5: 0 | W5: 182 | X5: =B5 -> UGRA | Y5: 3 | AK5: HERT | AL5: HULLA | AM5: 3 | AN5: =SUMIF(Drivers!$B$11:$B$222,"*-"&Constructors!$AL5&"-*",Drivers!C$11:C$222) -> 38 | AO5: =SUMIF(Drivers!$B$11:$B$222,"*-"&Constructors!$AL5&"-*",Drivers!D$11:D$222) -> 36 | AP5: 20 | AQ5: =SUMIF(Drivers!$B$11:$B$222,"*-"&Constructors!$AL5&"-*",Drivers!E$11:E$222) -> 42 | AR5: =SUMIF(Drivers!$B$11:$B$222,"*-"&Constructors!$AL5&"-*",Drivers!F$11:F$222) -> 22 | AS5: =SUMIF(Drivers!$B$11:$B$222,"*-"&Constructors!$AL5&"-*",Drivers!G$11:G$222) -> 0 | AT5: =SUMIF(Drivers!$B$11:$B$222,"*-"&Constructors!$AL5&"-*",Drivers!H$11:H$222) -> 0 | AV5: =SUMIF(Drivers!$B$11:$B$222,"*-"&Constructors!$AL5&"-*",Drivers!I$11:I$222) -> 0 | AW5: =SUMIF(Drivers!$B$11:$B$222,"*-"&Constructors!$AL5&"-*",Drivers!J$11:J$222) -> 0 | AY5: =SUMIF(Drivers!$B$11:$B$222,"*-"&Constructors!$AL5&"-*",Drivers!K$11:K$222) -> 0 | AZ5: =SUMIF(Drivers!$B$11:$B$222,"*-"&Constructors!$AL5&"-*",Drivers!L$11:L$222) -> 0 | BB5: =SUMIF(Drivers!$B$11:$B$222,"*-"&Constructors!$AL5&"-*",Drivers!M$11:M$222) -> 0 | BC5: =SUMIF(Drivers!$B$11:$B$222,"*-"&Constructors!$AL5&"-*",Drivers!N$11:N$222) -> 0 | BE5: =SUMIF(Drivers!$B$11:$B$222,"*-"&Constructors!$AL5&"-*",Drivers!O$11:O$222) -> 0 | BF5: =SUMIF(Drivers!$B$11:$B$222,"*-"&Constructors!$AL5&"-*",Drivers!P$11:P$222) -> 0 | BG5: =SUM(AN5:BF5) -> 158
A6: UVigo Motorsport | B6: VIGO | C6: 40 | D6: 46 | E6: 50 | F6: 32 | G6: 26 | H6: 25 | I6: 0 | J6: 0 | K6: 0 | L6: 0 | M6: 0 | N6: 0 | O6: 0 | P6: 0 | Q6: 0 | R6: 0 | S6: 0 | T6: 0 | U6: 0 | V6: 0 | W6: 179 | X6: =B6 -> VIGO | Y6: 4 | Z6: 1 | AK6: NCME Racing | AL6: NCME | AM6: 4 | AN6: =SUMIF(Drivers!$B$11:$B$222,"*-"&Constructors!$AL6&"-*",Drivers!C$11:C$222) -> 40 | AO6: =SUMIF(Drivers!$B$11:$B$222,"*-"&Constructors!$AL6&"-*",Drivers!D$11:D$222) -> 42 | AP6: 42 | AQ6: =SUMIF(Drivers!$B$11:$B$222,"*-"&Constructors!$AL6&"-*",Drivers!E$11:E$222) -> 22 | AR6: =SUMIF(Drivers!$B$11:$B$222,"*-"&Constructors!$AL6&"-*",Drivers!F$11:F$222) -> 42 | AS6: =SUMIF(Drivers!$B$11:$B$222,"*-"&Constructors!$AL6&"-*",Drivers!G$11:G$222) -> 0 | AT6: =SUMIF(Drivers!$B$11:$B$222,"*-"&Constructors!$AL6&"-*",Drivers!H$11:H$222) -> 0 | AV6: =SUMIF(Drivers!$B$11:$B$222,"*-"&Constructors!$AL6&"-*",Drivers!I$11:I$222) -> 0 | AW6: =SUMIF(Drivers!$B$11:$B$222,"*-"&Constructors!$AL6&"-*",Drivers!J$11:J$222) -> 0 | AY6: =SUMIF(Drivers!$B$11:$B$222,"*-"&Constructors!$AL6&"-*",Drivers!K$11:K$222) -> 0 | AZ6: =SUMIF(Drivers!$B$11:$B$222,"*-"&Constructors!$AL6&"-*",Drivers!L$11:L$222) -> 0 | BB6: =SUMIF(Drivers!$B$11:$B$222,"*-"&Constructors!$AL6&"-*",Drivers!M$11:M$222) -> 0 | BC6: =SUMIF(Drivers!$B$11:$B$222,"*-"&Constructors!$AL6&"-*",Drivers!N$11:N$222) -> 0 | BE6: =SUMIF(Drivers!$B$11:$B$222,"*-"&Constructors!$AL6&"-*",Drivers!O$11:O$222) -> 0 | BF6: =SUMIF(Drivers!$B$11:$B$222,"*-"&Constructors!$AL6&"-*",Drivers!P$11:P$222) -> 0 | BG6: =SUM(AN6:BF6) -> 188
A7: HERT | B7: HULLA | C7: 3 | D7: 38 | E7: 36 | F7: 20 | G7: 42 | H7: 22 | I7: 0 | J7: 0 | K7: 0 | L7: 0 | M7: 0 | N7: 0 | O7: 0 | P7: 0 | Q7: 0 | R7: 0 | S7: 0 | T7: 0 | U7: 0 | V7: 0 | W7: 158 | X7: =B7 -> HULLA | Y7: 5 | AK7: UWTSD Sim Racing Team | AL7: UWTSD | AM7: 5 | AN7: =SUMIF(Drivers!$B$11:$B$222,"*-"&Constructors!$AL7&"-*",Drivers!C$11:C$222) -> 16 | AO7: =SUMIF(Drivers!$B$11:$B$222,"*-"&Constructors!$AL7&"-*",Drivers!D$11:D$222) -> 40 | AQ7: =SUMIF(Drivers!$B$11:$B$222,"*-"&Constructors!$AL7&"-*",Drivers!E$11:E$222) -> 24 | AR7: =SUMIF(Drivers!$B$11:$B$222,"*-"&Constructors!$AL7&"-*",Drivers!F$11:F$222) -> 7 | AS7: =SUMIF(Drivers!$B$11:$B$222,"*-"&Constructors!$AL7&"-*",Drivers!G$11:G$222) -> 0 | AT7: =SUMIF(Drivers!$B$11:$B$222,"*-"&Constructors!$AL7&"-*",Drivers!H$11:H$222) -> 0 | AV7: =SUMIF(Drivers!$B$11:$B$222,"*-"&Constructors!$AL7&"-*",Drivers!I$11:I$222) -> 0 | AW7: =SUMIF(Drivers!$B$11:$B$222,"*-"&Constructors!$AL7&"-*",Drivers!J$11:J$222) -> 0 | AY7: =SUMIF(Drivers!$B$11:$B$222,"*-"&Constructors!$AL7&"-*",Drivers!K$11:K$222) -> 0 | AZ7: =SUMIF(Drivers!$B$11:$B$222,"*-"&Constructors!$AL7&"-*",Drivers!L$11:L$222) -> 0 | BB7: =SUMIF(Drivers!$B$11:$B$222,"*-"&Constructors!$AL7&"-*",Drivers!M$11:M$222) -> 0 | BC7: =SUMIF(Drivers!$B$11:$B$222,"*-"&Constructors!$AL7&"-*",Drivers!N$11:N$222) -> 0 | BE7: =SUMIF(Drivers!$B$11:$B$222,"*-"&Constructors!$AL7&"-*",Drivers!O$11:O$222) -> 0 | BF7: =SUMIF(Drivers!$B$11:$B$222,"*-"&Constructors!$AL7&"-*",Drivers!P$11:P$222) -> 0 | BG7: =SUM(AN7:BF7) -> 87
A8: Salford Racing | B8: SALF | C8: 6 | D8: 42 | E8: 25 | F8: 0 | G8: 36 | H8: 42 | I8: 0 | J8: 0 | K8: 0 | L8: 0 | M8: 0 | N8: 0 | O8: 0 | P8: 0 | Q8: 0 | R8: 0 | S8: 0 | T8: 0 | U8: 0 | V8: 0 | W8: 145 | X8: =B8 -> SALF | Y8: 6 | AK8: Salford Racing | AL8: SALF | AM8: 6 | AN8: =SUMIF(Drivers!$B$11:$B$222,"*-"&Constructors!$AL8&"-*",Drivers!C$11:C$222) -> 42 | AO8: =SUMIF(Drivers!$B$11:$B$222,"*-"&Constructors!$AL8&"-*",Drivers!D$11:D$222) -> 25 | AP8: 0 | AQ8: =SUMIF(Drivers!$B$11:$B$222,"*-"&Constructors!$AL8&"-*",Drivers!E$11:E$222) -> 36 | AR8: =SUMIF(Drivers!$B$11:$B$222,"*-"&Constructors!$AL8&"-*",Drivers!F$11:F$222) -> 42 | AS8: =SUMIF(Drivers!$B$11:$B$222,"*-"&Constructors!$AL8&"-*",Drivers!G$11:G$222) -> 0 | AT8: =SUMIF(Drivers!$B$11:$B$222,"*-"&Constructors!$AL8&"-*",Drivers!H$11:H$222) -> 0 | AV8: =SUMIF(Drivers!$B$11:$B$222,"*-"&Constructors!$AL8&"-*",Drivers!I$11:I$222) -> 0 | AW8: =SUMIF(Drivers!$B$11:$B$222,"*-"&Constructors!$AL8&"-*",Drivers!J$11:J$222) -> 0 | AY8: =SUMIF(Drivers!$B$11:$B$222,"*-"&Constructors!$AL8&"-*",Drivers!K$11:K$222) -> 0 | AZ8: =SUMIF(Drivers!$B$11:$B$222,"*-"&Constructors!$AL8&"-*",Drivers!L$11:L$222) -> 0 | BB8: =SUMIF(Drivers!$B$11:$B$222,"*-"&Constructors!$AL8&"-*",Drivers!M$11:M$222) -> 0 | BC8: =SUMIF(Drivers!$B$11:$B$222,"*-"&Constructors!$AL8&"-*",Drivers!N$11:N$222) -> 0 | BE8: =SUMIF(Drivers!$B$11:$B$222,"*-"&Constructors!$AL8&"-*",Drivers!O$11:O$222) -> 0 | BF8: =SUMIF(Drivers!$B$11:$B$222,"*-"&Constructors!$AL8&"-*",Drivers!P$11:P$222) -> 0 | BG8: =SUM(AN8:BF8) -> 145
A9: UCD Formula Student | B9: UCD | C9: 35 | D9: 29 | E9: 26 | F9: 40 | G9: 19 | H9: 28 | I9: 0 | J9: 0 | K9: 0 | L9: 0 | M9: 0 | N9: 0 | O9: 0 | P9: 0 | Q9: 0 | R9: 0 | S9: 0 | T9: 0 | U9: 0 | V9: 0 | W9: 142 | X9: =B9 -> UCD | Y9: 7 | AK9: USM | AL9: USM | AM9: 7 | AN9: =SUMIF(Drivers!$B$11:$B$222,"*-"&Constructors!$AL9&"-*",Drivers!C$11:C$222) -> 22 | AO9: =SUMIF(Drivers!$B$11:$B$222,"*-"&Constructors!$AL9&"-*",Drivers!D$11:D$222) -> 20 | AP9: 36 | AQ9: =SUMIF(Drivers!$B$11:$B$222,"*-"&Constructors!$AL9&"-*",Drivers!E$11:E$222) -> 0 | AR9: =SUMIF(Drivers!$B$11:$B$222,"*-"&Constructors!$AL9&"-*",Drivers!F$11:F$222) -> 0 | AS9: =SUMIF(Drivers!$B$11:$B$222,"*-"&Constructors!$AL9&"-*",Drivers!G$11:G$222) -> 0 | AT9: =SUMIF(Drivers!$B$11:$B$222,"*-"&Constructors!$AL9&"-*",Drivers!H$11:H$222) -> 0 | AV9: =SUMIF(Drivers!$B$11:$B$222,"*-"&Constructors!$AL9&"-*",Drivers!I$11:I$222) -> 0 | AW9: =SUMIF(Drivers!$B$11:$B$222,"*-"&Constructors!$AL9&"-*",Drivers!J$11:J$222) -> 0 | AY9: =SUMIF(Drivers!$B$11:$B$222,"*-"&Constructors!$AL9&"-*",Drivers!K$11:K$222) -> 0 | AZ9: =SUMIF(Drivers!$B$11:$B$222,"*-"&Constructors!$AL9&"-*",Drivers!L$11:L$222) -> 0 | BB9: =SUMIF(Drivers!$B$11:$B$222,"*-"&Constructors!$AL9&"-*",Drivers!M$11:M$222) -> 0 | BC9: =SUMIF(Drivers!$B$11:$B$222,"*-"&Constructors!$AL9&"-*",Drivers!N$11:N$222) -> 0 | BE9: =SUMIF(Drivers!$B$11:$B$222,"*-"&Constructors!$AL9&"-*",Drivers!O$11:O$222) -> 0 | BF9: =SUMIF(Drivers!$B$11:$B$222,"*-"&Constructors!$AL9&"-*",Drivers!P$11:P$222) -> 0 | BG9: =SUM(AN9:BF9) -> 78
A10: UPRacing Alternative Fuel | B10: UPRAF | C10: 48 | D10: 50 | E10: 15 | F10: 0 | G10: 39 | H10: 32 | I10: 0 | J10: 0 | K10: 0 | L10: 0 | M10: 0 | N10: 0 | O10: 0 | P10: 0 | Q10: 0 | R10: 0 | S10: 0 | T10: 0 | U10: 0 | V10: 0 | W10: 136 | X10: =B10 -> UPRAF | Y10: 8 | AK10: Cardiff Racing | AL10: CARD | AM10: 8 | AN10: =SUMIF(Drivers!$B$11:$B$222,"*-"&Constructors!$AL10&"-*",Drivers!C$11:C$222) -> 30 | AO10: =SUMIF(Drivers!$B$11:$B$222,"*-"&Constructors!$AL10&"-*",Drivers!D$11:D$222) -> 17 | AP10: 28 | AQ10: =SUMIF(Drivers!$B$11:$B$222,"*-"&Constructors!$AL10&"-*",Drivers!E$11:E$222) -> 18 | AR10: =SUMIF(Drivers!$B$11:$B$222,"*-"&Constructors!$AL10&"-*",Drivers!F$11:F$222) -> 36 | AS10: =SUMIF(Drivers!$B$11:$B$222,"*-"&Constructors!$AL10&"-*",Drivers!G$11:G$222) -> 0 | AT10: =SUMIF(Drivers!$B$11:$B$222,"*-"&Constructors!$AL10&"-*",Drivers!H$11:H$222) -> 0 | AV10: =SUMIF(Drivers!$B$11:$B$222,"*-"&Constructors!$AL10&"-*",Drivers!I$11:I$222) -> 0 | AW10: =SUMIF(Drivers!$B$11:$B$222,"*-"&Constructors!$AL10&"-*",Drivers!J$11:J$222) -> 0 | AY10: =SUMIF(Drivers!$B$11:$B$222,"*-"&Constructors!$AL10&"-*",Drivers!K$11:K$222) -> 0 | AZ10: =SUMIF(Drivers!$B$11:$B$222,"*-"&Constructors!$AL10&"-*",Drivers!L$11:L$222) -> 0 | BB10: =SUMIF(Drivers!$B$11:$B$222,"*-"&Constructors!$AL10&"-*",Drivers!M$11:M$222) -> 0 | BC10: =SUMIF(Drivers!$B$11:$B$222,"*-"&Constructors!$AL10&"-*",Drivers!N$11:N$222) -> 0 | BE10: =SUMIF(Drivers!$B$11:$B$222,"*-"&Constructors!$AL10&"-*",Drivers!O$11:O$222) -> 0 | BF10: =SUMIF(Drivers!$B$11:$B$222,"*-"&Constructors!$AL10&"-*",Drivers!P$11:P$222) -> 0 | BG10: =SUM(AN10:BF10) -> 129
A11: Cardiff Racing | B11: CARD | C11: 8 | D11: 30 | E11: 17 | F11: 28 | G11: 18 | H11: 36 | I11: 0 | J11: 0 | K11: 0 | L11: 0 | M11: 0 | N11: 0 | O11: 0 | P11: 0 | Q11: 0 | R11: 0 | S11: 0 | T11: 0 | U11: 0 | V11: 0 | W11: 129 | X11: =B11 -> CARD | Y11: 9 | AK11: Fuosr mofu Alala Svtau)dent Vitoria | AL11: VIT | AM11: 9 | AN11: =SUMIF(Drivers!$B$11:$B$222,"*-"&Constructors!$AL11&"-*",Drivers!C$11:C$222) -> 8 | AO11: =SUMIF(Drivers!$B$11:$B$222,"*-"&Constructors!$AL11&"-*",Drivers!D$11:D$222) -> 14 | AQ11: =SUMIF(Drivers!$B$11:$B$222,"*-"&Constructors!$AL11&"-*",Drivers!E$11:E$222) -> 30 | AR11: =SUMIF(Drivers!$B$11:$B$222,"*-"&Constructors!$AL11&"-*",Drivers!F$11:F$222) -> 0 | AS11: =SUMIF(Drivers!$B$11:$B$222,"*-"&Constructors!$AL11&"-*",Drivers!G$11:G$222) -> 0 | AT11: =SUMIF(Drivers!$B$11:$B$222,"*-"&Constructors!$AL11&"-*",Drivers!H$11:H$222) -> 0 | AV11: =SUMIF(Drivers!$B$11:$B$222,"*-"&Constructors!$AL11&"-*",Drivers!I$11:I$222) -> 0 | AW11: =SUMIF(Drivers!$B$11:$B$222,"*-"&Constructors!$AL11&"-*",Drivers!J$11:J$222) -> 0 | AY11: =SUMIF(Drivers!$B$11:$B$222,"*-"&Constructors!$AL11&"-*",Drivers!K$11:K$222) -> 0 | AZ11: =SUMIF(Drivers!$B$11:$B$222,"*-"&Constructors!$AL11&"-*",Drivers!L$11:L$222) -> 0 | BB11: =SUMIF(Drivers!$B$11:$B$222,"*-"&Constructors!$AL11&"-*",Drivers!M$11:M$222) -> 0 | BC11: =SUMIF(Drivers!$B$11:$B$222,"*-"&Constructors!$AL11&"-*",Drivers!N$11:N$222) -> 0 | BE11: =SUMIF(Drivers!$B$11:$B$222,"*-"&Constructors!$AL11&"-*",Drivers!O$11:O$222) -> 0 | BF11: =SUMIF(Drivers!$B$11:$B$222,"*-"&Constructors!$AL11&"-*",Drivers!P$11:P$222) -> 0 | BG11: =SUM(AN11:BF11) -> 52
A12: Team Bath Racing Electric | B12: BATH | C12: 43 | D12: 26 | E12: 34 | F12: 0 | G12: 26 | H12: 38 | I12: 0 | J12: 0 | K12: 0 | L12: 0 | M12: 0 | N12: 0 | O12: 0 | P12: 0 | Q12: 0 | R12: 0 | S12: 0 | T12: 0 | U12: 0 | V12: 0 | W12: 124 | X12: =B12 -> BATH | Y12: 10 | AK12: ION Racing | AL12: ION | AM12: 10 | AN12: =SUMIF(Drivers!$B$11:$B$222,"*-"&Constructors!$AL12&"-*",Drivers!C$11:C$222) -> 0 | AO12: =SUMIF(Drivers!$B$11:$B$222,"*-"&Constructors!$AL12&"-*",Drivers!D$11:D$222) -> 0 | AQ12: =SUMIF(Drivers!$B$11:$B$222,"*-"&Constructors!$AL12&"-*",Drivers!E$11:E$222) -> 11 | AR12: =SUMIF(Drivers!$B$11:$B$222,"*-"&Constructors!$AL12&"-*",Drivers!F$11:F$222) -> 20 | AS12: =SUMIF(Drivers!$B$11:$B$222,"*-"&Constructors!$AL12&"-*",Drivers!G$11:G$222) -> 0 | AT12: =SUMIF(Drivers!$B$11:$B$222,"*-"&Constructors!$AL12&"-*",Drivers!H$11:H$222) -> 0 | AV12: =SUMIF(Drivers!$B$11:$B$222,"*-"&Constructors!$AL12&"-*",Drivers!I$11:I$222) -> 0 | AW12: =SUMIF(Drivers!$B$11:$B$222,"*-"&Constructors!$AL12&"-*",Drivers!J$11:J$222) -> 0 | AY12: =SUMIF(Drivers!$B$11:$B$222,"*-"&Constructors!$AL12&"-*",Drivers!K$11:K$222) -> 0 | AZ12: =SUMIF(Drivers!$B$11:$B$222,"*-"&Constructors!$AL12&"-*",Drivers!L$11:L$222) -> 0 | BB12: =SUMIF(Drivers!$B$11:$B$222,"*-"&Constructors!$AL12&"-*",Drivers!M$11:M$222) -> 0 | BC12: =SUMIF(Drivers!$B$11:$B$222,"*-"&Constructors!$AL12&"-*",Drivers!N$11:N$222) -> 0 | BE12: =SUMIF(Drivers!$B$11:$B$222,"*-"&Constructors!$AL12&"-*",Drivers!O$11:O$222) -> 0 | BF12: =SUMIF(Drivers!$B$11:$B$222,"*-"&Constructors!$AL12&"-*",Drivers!P$11:P$222) -> 0 | BG12: =SUM(AN12:BF12) -> 31
A13: oRgeyd Bird Racing | B13: RBRT | C13: 41 | D13: 15 | E13: 32 | F13: 20 | G13: 16 | H13: 26 | I13: 0 | J13: 0 | K13: 0 | L13: 0 | M13: 0 | N13: 0 | O13: 0 | P13: 0 | Q13: 0 | R13: 0 | S13: 0 | T13: 0 | U13: 0 | V13: 0 | W13: 109 | X13: =B13 -> RBRT | Y13: 11 | AK13: Full Blue Racing | AL13: CAMA | AM13: 11 | AN13: =SUMIF(Drivers!$B$11:$B$222,"*-"&Constructors!$AL13&"-*",Drivers!C$11:C$222) -> 12 | AO13: =SUMIF(Drivers!$B$11:$B$222,"*-"&Constructors!$AL13&"-*",Drivers!D$11:D$222) -> 14 | AQ13: =SUMIF(Drivers!$B$11:$B$222,"*-"&Constructors!$AL13&"-*",Drivers!E$11:E$222) -> 0 | AR13: =SUMIF(Drivers!$B$11:$B$222,"*-"&Constructors!$AL13&"-*",Drivers!F$11:F$222) -> 0 | AS13: =SUMIF(Drivers!$B$11:$B$222,"*-"&Constructors!$AL13&"-*",Drivers!G$11:G$222) -> 0 | AT13: =SUMIF(Drivers!$B$11:$B$222,"*-"&Constructors!$AL13&"-*",Drivers!H$11:H$222) -> 0 | AV13: =SUMIF(Drivers!$B$11:$B$222,"*-"&Constructors!$AL13&"-*",Drivers!I$11:I$222) -> 0 | AW13: =SUMIF(Drivers!$B$11:$B$222,"*-"&Constructors!$AL13&"-*",Drivers!J$11:J$222) -> 0 | AY13: =SUMIF(Drivers!$B$11:$B$222,"*-"&Constructors!$AL13&"-*",Drivers!K$11:K$222) -> 0 | AZ13: =SUMIF(Drivers!$B$11:$B$222,"*-"&Constructors!$AL13&"-*",Drivers!L$11:L$222) -> 0 | BB13: =SUMIF(Drivers!$B$11:$B$222,"*-"&Constructors!$AL13&"-*",Drivers!M$11:M$222) -> 0 | BC13: =SUMIF(Drivers!$B$11:$B$222,"*-"&Constructors!$AL13&"-*",Drivers!N$11:N$222) -> 0 | BE13: =SUMIF(Drivers!$B$11:$B$222,"*-"&Constructors!$AL13&"-*",Drivers!O$11:O$222) -> 0 | BF13: =SUMIF(Drivers!$B$11:$B$222,"*-"&Constructors!$AL13&"-*",Drivers!P$11:P$222) -> 0 | BG13: =SUM(AN13:BF13) -> 26
A14: MTU Formula Student | B14: MTU | C14: 36 | D14: 14 | E14: 19 | F14: 20 | G14: 32 | H14: 18 | I14: 0 | J14: 0 | K14: 0 | L14: 0 | M14: 0 | N14: 0 | O14: 0 | P14: 0 | Q14: 0 | R14: 0 | S14: 0 | T14: 0 | U14: 0 | V14: 0 | W14: 103 | X14: =B14 -> MTU | Y14: 12 | AK14: Kingston Racing | AL14: KING | AM14: 12 | AN14: =SUMIF(Drivers!$B$11:$B$222,"*-"&Constructors!$AL14&"-*",Drivers!C$11:C$222) -> 1 | AO14: =SUMIF(Drivers!$B$11:$B$222,"*-"&Constructors!$AL14&"-*",Drivers!D$11:D$222) -> 0 | AQ14: =SUMIF(Drivers!$B$11:$B$222,"*-"&Constructors!$AL14&"-*",Drivers!E$11:E$222) -> 0 | AR14: =SUMIF(Drivers!$B$11:$B$222,"*-"&Constructors!$AL14&"-*",Drivers!F$11:F$222) -> 15 | AS14: =SUMIF(Drivers!$B$11:$B$222,"*-"&Constructors!$AL14&"-*",Drivers!G$11:G$222) -> 0 | AT14: =SUMIF(Drivers!$B$11:$B$222,"*-"&Constructors!$AL14&"-*",Drivers!H$11:H$222) -> 0 | AV14: =SUMIF(Drivers!$B$11:$B$222,"*-"&Constructors!$AL14&"-*",Drivers!I$11:I$222) -> 0 | AW14: =SUMIF(Drivers!$B$11:$B$222,"*-"&Constructors!$AL14&"-*",Drivers!J$11:J$222) -> 0 | AY14: =SUMIF(Drivers!$B$11:$B$222,"*-"&Constructors!$AL14&"-*",Drivers!K$11:K$222) -> 0 | AZ14: =SUMIF(Drivers!$B$11:$B$222,"*-"&Constructors!$AL14&"-*",Drivers!L$11:L$222) -> 0 | BB14: =SUMIF(Drivers!$B$11:$B$222,"*-"&Constructors!$AL14&"-*",Drivers!M$11:M$222) -> 0 | BC14: =SUMIF(Drivers!$B$11:$B$222,"*-"&Constructors!$AL14&"-*",Drivers!N$11:N$222) -> 0 | BE14: =SUMIF(Drivers!$B$11:$B$222,"*-"&Constructors!$AL14&"-*",Drivers!O$11:O$222) -> 0 | BF14: =SUMIF(Drivers!$B$11:$B$222,"*-"&Constructors!$AL14&"-*",Drivers!P$11:P$222) -> 0 | BG14: =SUM(AN14:BF14) -> 16
A15: Queen Mary Formula Student | B15: QMFS | C15: 51 | D15: 2 | E15: 38 | F15: 30 | G15: 12 | H15: 18 | I15: 0 | J15: 0 | K15: 0 | L15: 0 | M15: 0 | N15: 0 | O15: 0 | P15: 0 | Q15: 0 | R15: 0 | S15: 0 | T15: 0 | U15: 0 | V15: 0 | W15: 100 | X15: =B15 -> QMFS | Y15: 13 | AK15: OUSR - Oxford University Sim Racing | AL15: OUSR | AM15: 13 | AN15: =SUMIF(Drivers!$B$11:$B$222,"*-"&Constructors!$AL15&"-*",Drivers!C$11:C$222) -> 0 | AO15: =SUMIF(Drivers!$B$11:$B$222,"*-"&Constructors!$AL15&"-*",Drivers!D$11:D$222) -> 0 | AQ15: =SUMIF(Drivers!$B$11:$B$222,"*-"&Constructors!$AL15&"-*",Drivers!E$11:E$222) -> 0 | AR15: =SUMIF(Drivers!$B$11:$B$222,"*-"&Constructors!$AL15&"-*",Drivers!F$11:F$222) -> 0 | AS15: =SUMIF(Drivers!$B$11:$B$222,"*-"&Constructors!$AL15&"-*",Drivers!G$11:G$222) -> 0 | AT15: =SUMIF(Drivers!$B$11:$B$222,"*-"&Constructors!$AL15&"-*",Drivers!H$11:H$222) -> 0 | AV15: =SUMIF(Drivers!$B$11:$B$222,"*-"&Constructors!$AL15&"-*",Drivers!I$11:I$222) -> 0 | AW15: =SUMIF(Drivers!$B$11:$B$222,"*-"&Constructors!$AL15&"-*",Drivers!J$11:J$222) -> 0 | AY15: =SUMIF(Drivers!$B$11:$B$222,"*-"&Constructors!$AL15&"-*",Drivers!K$11:K$222) -> 0 | AZ15: =SUMIF(Drivers!$B$11:$B$222,"*-"&Constructors!$AL15&"-*",Drivers!L$11:L$222) -> 0 | BB15: =SUMIF(Drivers!$B$11:$B$222,"*-"&Constructors!$AL15&"-*",Drivers!M$11:M$222) -> 0 | BC15: =SUMIF(Drivers!$B$11:$B$222,"*-"&Constructors!$AL15&"-*",Drivers!N$11:N$222) -> 0 | BE15: =SUMIF(Drivers!$B$11:$B$222,"*-"&Constructors!$AL15&"-*",Drivers!O$11:O$222) -> 0 | BF15: =SUMIF(Drivers!$B$11:$B$222,"*-"&Constructors!$AL15&"-*",Drivers!P$11:P$222) -> 0 | BG15: =SUM(AN15:BF15) -> 0
A16: LJMU e-Racing | B16: LJMU | C16: 50 | D16: 0 | E16: 24 | F16: 0 | G16: 40 | H16: 30 | I16: 0 | J16: 0 | K16: 0 | L16: 0 | M16: 0 | N16: 0 | O16: 0 | P16: 0 | Q16: 0 | R16: 0 | S16: 0 | T16: 0 | U16: 0 | V16: 0 | W16: 94 | X16: =B16 -> LJMU | Y16: 14 | AK16: Team Aberdeen University (TAU) | AL16: TAU | AM16: 14 | AN16: =SUMIF(Drivers!$B$11:$B$222,"*-"&Constructors!$AL16&"-*",Drivers!C$11:C$222) -> 5 | AO16: =SUMIF(Drivers!$B$11:$B$222,"*-"&Constructors!$AL16&"-*",Drivers!D$11:D$222) -> 19 | AP16: 0 | AQ16: =SUMIF(Drivers!$B$11:$B$222,"*-"&Constructors!$AL16&"-*",Drivers!E$11:E$222) -> 14 | AR16: =SUMIF(Drivers!$B$11:$B$222,"*-"&Constructors!$AL16&"-*",Drivers!F$11:F$222) -> 17 | AS16: =SUMIF(Drivers!$B$11:$B$222,"*-"&Constructors!$AL16&"-*",Drivers!G$11:G$222) -> 0 | AT16: =SUMIF(Drivers!$B$11:$B$222,"*-"&Constructors!$AL16&"-*",Drivers!H$11:H$222) -> 0 | AV16: =SUMIF(Drivers!$B$11:$B$222,"*-"&Constructors!$AL16&"-*",Drivers!I$11:I$222) -> 0 | AW16: =SUMIF(Drivers!$B$11:$B$222,"*-"&Constructors!$AL16&"-*",Drivers!J$11:J$222) -> 0 | AY16: =SUMIF(Drivers!$B$11:$B$222,"*-"&Constructors!$AL16&"-*",Drivers!K$11:K$222) -> 0 | AZ16: =SUMIF(Drivers!$B$11:$B$222,"*-"&Constructors!$AL16&"-*",Drivers!L$11:L$222) -> 0 | BB16: =SUMIF(Drivers!$B$11:$B$222,"*-"&Constructors!$AL16&"-*",Drivers!M$11:M$222) -> 0 | BC16: =SUMIF(Drivers!$B$11:$B$222,"*-"&Constructors!$AL16&"-*",Drivers!N$11:N$222) -> 0 | BE16: =SUMIF(Drivers!$B$11:$B$222,"*-"&Constructors!$AL16&"-*",Drivers!O$11:O$222) -> 0 | BF16: =SUMIF(Drivers!$B$11:$B$222,"*-"&Constructors!$AL16&"-*",Drivers!P$11:P$222) -> 0 | BG16: =SUM(AN16:BF16) -> 55
A17: XRacing Exeter | B17: EXET | C17: 38 | D17: 36 | E17: 8 | F17: 0 | G17: 20 | H17: 24 | I17: 0 | J17: 0 | K17: 0 | L17: 0 | M17: 0 | N17: 0 | O17: 0 | P17: 0 | Q17: 0 | R17: 0 | S17: 0 | T17: 0 | U17: 0 | V17: 0 | W17: 88 | X17: =B17 -> EXET | Y17: 15 | Z17: 1 | AK17: Lassonde Motorsports | AL17: LASS | AM17: 15 | AN17: =SUMIF(Drivers!$B$11:$B$222,"*-"&Constructors!$AL17&"-*",Drivers!C$11:C$222) -> 5 | AO17: =SUMIF(Drivers!$B$11:$B$222,"*-"&Constructors!$AL17&"-*",Drivers!D$11:D$222) -> 20 | AQ17: =SUMIF(Drivers!$B$11:$B$222,"*-"&Constructors!$AL17&"-*",Drivers!E$11:E$222) -> 0 | AR17: =SUMIF(Drivers!$B$11:$B$222,"*-"&Constructors!$AL17&"-*",Drivers!F$11:F$222) -> 0 | AS17: =SUMIF(Drivers!$B$11:$B$222,"*-"&Constructors!$AL17&"-*",Drivers!G$11:G$222) -> 0 | AT17: =SUMIF(Drivers!$B$11:$B$222,"*-"&Constructors!$AL17&"-*",Drivers!H$11:H$222) -> 0 | AV17: =SUMIF(Drivers!$B$11:$B$222,"*-"&Constructors!$AL17&"-*",Drivers!I$11:I$222) -> 0 | AW17: =SUMIF(Drivers!$B$11:$B$222,"*-"&Constructors!$AL17&"-*",Drivers!J$11:J$222) -> 0 | AY17: =SUMIF(Drivers!$B$11:$B$222,"*-"&Constructors!$AL17&"-*",Drivers!K$11:K$222) -> 0 | AZ17: =SUMIF(Drivers!$B$11:$B$222,"*-"&Constructors!$AL17&"-*",Drivers!L$11:L$222) -> 0 | BB17: =SUMIF(Drivers!$B$11:$B$222,"*-"&Constructors!$AL17&"-*",Drivers!M$11:M$222) -> 0 | BC17: =SUMIF(Drivers!$B$11:$B$222,"*-"&Constructors!$AL17&"-*",Drivers!N$11:N$222) -> 0 | BE17: =SUMIF(Drivers!$B$11:$B$222,"*-"&Constructors!$AL17&"-*",Drivers!O$11:O$222) -> 0 | BF17: =SUMIF(Drivers!$B$11:$B$222,"*-"&Constructors!$AL17&"-*",Drivers!P$11:P$222) -> 0 | BG17: =SUM(AN17:BF17) -> 25
A18: UWTSD Sim Racing Team | B18: UWTSD | C18: 5 | D18: 16 | E18: 40 | F18: 0 | G18: 24 | H18: 7 | I18: 0 | J18: 0 | K18: 0 | L18: 0 | M18: 0 | N18: 0 | O18: 0 | P18: 0 | Q18: 0 | R18: 0 | S18: 0 | T18: 0 | U18: 0 | V18: 0 | W18: 87 | X18: =B18 -> UWTSD | Y18: 16 | AK18: Manchester Stinger Motorsports | AL18: MAN | AM18: 16 | AN18: =SUMIF(Drivers!$B$11:$B$222,"*-"&Constructors!$AL18&"-*",Drivers!C$11:C$222) -> 20 | AO18: =SUMIF(Drivers!$B$11:$B$222,"*-"&Constructors!$AL18&"-*",Drivers!D$11:D$222) -> 5 | AP18: 0 | AQ18: =SUMIF(Drivers!$B$11:$B$222,"*-"&Constructors!$AL18&"-*",Drivers!E$11:E$222) -> 14 | AR18: =SUMIF(Drivers!$B$11:$B$222,"*-"&Constructors!$AL18&"-*",Drivers!F$11:F$222) -> 14 | AS18: =SUMIF(Drivers!$B$11:$B$222,"*-"&Constructors!$AL18&"-*",Drivers!G$11:G$222) -> 0 | AT18: =SUMIF(Drivers!$B$11:$B$222,"*-"&Constructors!$AL18&"-*",Drivers!H$11:H$222) -> 0 | AV18: =SUMIF(Drivers!$B$11:$B$222,"*-"&Constructors!$AL18&"-*",Drivers!I$11:I$222) -> 0 | AW18: =SUMIF(Drivers!$B$11:$B$222,"*-"&Constructors!$AL18&"-*",Drivers!J$11:J$222) -> 0 | AY18: =SUMIF(Drivers!$B$11:$B$222,"*-"&Constructors!$AL18&"-*",Drivers!K$11:K$222) -> 0 | AZ18: =SUMIF(Drivers!$B$11:$B$222,"*-"&Constructors!$AL18&"-*",Drivers!L$11:L$222) -> 0 | BB18: =SUMIF(Drivers!$B$11:$B$222,"*-"&Constructors!$AL18&"-*",Drivers!M$11:M$222) -> 0 | BC18: =SUMIF(Drivers!$B$11:$B$222,"*-"&Constructors!$AL18&"-*",Drivers!N$11:N$222) -> 0 | BE18: =SUMIF(Drivers!$B$11:$B$222,"*-"&Constructors!$AL18&"-*",Drivers!O$11:O$222) -> 0 | BF18: =SUMIF(Drivers!$B$11:$B$222,"*-"&Constructors!$AL18&"-*",Drivers!P$11:P$222) -> 0 | BG18: =SUM(AN18:BF18) -> 53
A19: Staffordshire Uni Racing | B19: STAF | C19: 21 | D19: 22 | E19: 0 | F19: 20 | G19: 28 | H19: 16 | I19: 0 | J19: 0 | K19: 0 | L19: 0 | M19: 0 | N19: 0 | O19: 0 | P19: 0 | Q19: 0 | R19: 0 | S19: 0 | T19: 0 | U19: 0 | V19: 0 | W19: 86 | X19: =B19 -> STAF | Y19: 17 | AK19: UCL Formula Student | AL19: UCL | AM19: 17 | AN19: =SUMIF(Drivers!$B$11:$B$222,"*-"&Constructors!$AL19&"-*",Drivers!C$11:C$222) -> 3 | AO19: =SUMIF(Drivers!$B$11:$B$222,"*-"&Constructors!$AL19&"-*",Drivers!D$11:D$222) -> 12 | AP19: 38 | AQ19: =SUMIF(Drivers!$B$11:$B$222,"*-"&Constructors!$AL19&"-*",Drivers!E$11:E$222) -> 1 | AR19: =SUMIF(Drivers!$B$11:$B$222,"*-"&Constructors!$AL19&"-*",Drivers!F$11:F$222) -> 0 | AS19: =SUMIF(Drivers!$B$11:$B$222,"*-"&Constructors!$AL19&"-*",Drivers!G$11:G$222) -> 0 | AT19: =SUMIF(Drivers!$B$11:$B$222,"*-"&Constructors!$AL19&"-*",Drivers!H$11:H$222) -> 0 | AV19: =SUMIF(Drivers!$B$11:$B$222,"*-"&Constructors!$AL19&"-*",Drivers!I$11:I$222) -> 0 | AW19: =SUMIF(Drivers!$B$11:$B$222,"*-"&Constructors!$AL19&"-*",Drivers!J$11:J$222) -> 0 | AY19: =SUMIF(Drivers!$B$11:$B$222,"*-"&Constructors!$AL19&"-*",Drivers!K$11:K$222) -> 0 | AZ19: =SUMIF(Drivers!$B$11:$B$222,"*-"&Constructors!$AL19&"-*",Drivers!L$11:L$222) -> 0 | BB19: =SUMIF(Drivers!$B$11:$B$222,"*-"&Constructors!$AL19&"-*",Drivers!M$11:M$222) -> 0 | BC19: =SUMIF(Drivers!$B$11:$B$222,"*-"&Constructors!$AL19&"-*",Drivers!N$11:N$222) -> 0 | BE19: =SUMIF(Drivers!$B$11:$B$222,"*-"&Constructors!$AL19&"-*",Drivers!O$11:O$222) -> 0 | BF19: =SUMIF(Drivers!$B$11:$B$222,"*-"&Constructors!$AL19&"-*",Drivers!P$11:P$222) -> 0 | BG19: =SUM(AN19:BF19) -> 54
A20: Jorvik Racing | B20: YORKA | C20: 19 | D20: 26 | E20: 10 | F20: 26 | G20: 16 | H20: 5 | I20: 0 | J20: 0 | K20: 0 | L20: 0 | M20: 0 | N20: 0 | O20: 0 | P20: 0 | Q20: 0 | R20: 0 | S20: 0 | T20: 0 | U20: 0 | V20: 0 | W20: 83 | X20: =B20 -> YORKA | Y20: 18 | Z20: 1 | AK20: Formula Student Team Napier | AL20: FSTN | AM20: 18 | AN20: =SUMIF(Drivers!$B$11:$B$222,"*-"&Constructors!$AL20&"-*",Drivers!C$11:C$222) -> 19 | AO20: =SUMIF(Drivers!$B$11:$B$222,"*-"&Constructors!$AL20&"-*",Drivers!D$11:D$222) -> 0 | AQ20: =SUMIF(Drivers!$B$11:$B$222,"*-"&Constructors!$AL20&"-*",Drivers!E$11:E$222) -> 6 | AR20: =SUMIF(Drivers!$B$11:$B$222,"*-"&Constructors!$AL20&"-*",Drivers!F$11:F$222) -> 0 | AS20: =SUMIF(Drivers!$B$11:$B$222,"*-"&Constructors!$AL20&"-*",Drivers!G$11:G$222) -> 0 | AT20: =SUMIF(Drivers!$B$11:$B$222,"*-"&Constructors!$AL20&"-*",Drivers!H$11:H$222) -> 0 | AV20: =SUMIF(Drivers!$B$11:$B$222,"*-"&Constructors!$AL20&"-*",Drivers!I$11:I$222) -> 0 | AW20: =SUMIF(Drivers!$B$11:$B$222,"*-"&Constructors!$AL20&"-*",Drivers!J$11:J$222) -> 0 | AY20: =SUMIF(Drivers!$B$11:$B$222,"*-"&Constructors!$AL20&"-*",Drivers!K$11:K$222) -> 0 | AZ20: =SUMIF(Drivers!$B$11:$B$222,"*-"&Constructors!$AL20&"-*",Drivers!L$11:L$222) -> 0 | BB20: =SUMIF(Drivers!$B$11:$B$222,"*-"&Constructors!$AL20&"-*",Drivers!M$11:M$222) -> 0 | BC20: =SUMIF(Drivers!$B$11:$B$222,"*-"&Constructors!$AL20&"-*",Drivers!N$11:N$222) -> 0 | BE20: =SUMIF(Drivers!$B$11:$B$222,"*-"&Constructors!$AL20&"-*",Drivers!O$11:O$222) -> 0 | BF20: =SUMIF(Drivers!$B$11:$B$222,"*-"&Constructors!$AL20&"-*",Drivers!P$11:P$222) -> 0 | BG20: =SUM(AN20:BF20) -> 25
A21: UB Racing | B21: UBR | C21: 31 | D21: 14 | E21: 0 | F21: 34 | G21: 18 | H21: 14 | I21: 0 | J21: 0 | K21: 0 | L21: 0 | M21: 0 | N21: 0 | O21: 0 | P21: 0 | Q21: 0 | R21: 0 | S21: 0 | T21: 0 | U21: 0 | V21: 0 | W21: 80 | X21: =B21 -> UBR | Y21: 19 | AK21: Jorvik Racing | AL21: YORKA | AM21: 19 | AN21: =SUMIF(Drivers!$B$11:$B$222,"*-"&Constructors!$AL21&"-*",Drivers!C$11:C$222) -> 26 | AO21: =SUMIF(Drivers!$B$11:$B$222,"*-"&Constructors!$AL21&"-*",Drivers!D$11:D$222) -> 10 | AP21: 26 | AQ21: =SUMIF(Drivers!$B$11:$B$222,"*-"&Constructors!$AL21&"-*",Drivers!E$11:E$222) -> 16 | AR21: =SUMIF(Drivers!$B$11:$B$222,"*-"&Constructors!$AL21&"-*",Drivers!F$11:F$222) -> 5 | AS21: =SUMIF(Drivers!$B$11:$B$222,"*-"&Constructors!$AL21&"-*",Drivers!G$11:G$222) -> 0 | AT21: =SUMIF(Drivers!$B$11:$B$222,"*-"&Constructors!$AL21&"-*",Drivers!H$11:H$222) -> 0 | AV21: =SUMIF(Drivers!$B$11:$B$222,"*-"&Constructors!$AL21&"-*",Drivers!I$11:I$222) -> 0 | AW21: =SUMIF(Drivers!$B$11:$B$222,"*-"&Constructors!$AL21&"-*",Drivers!J$11:J$222) -> 0 | AY21: =SUMIF(Drivers!$B$11:$B$222,"*-"&Constructors!$AL21&"-*",Drivers!K$11:K$222) -> 0 | AZ21: =SUMIF(Drivers!$B$11:$B$222,"*-"&Constructors!$AL21&"-*",Drivers!L$11:L$222) -> 0 | BB21: =SUMIF(Drivers!$B$11:$B$222,"*-"&Constructors!$AL21&"-*",Drivers!M$11:M$222) -> 0 | BC21: =SUMIF(Drivers!$B$11:$B$222,"*-"&Constructors!$AL21&"-*",Drivers!N$11:N$222) -> 0 | BE21: =SUMIF(Drivers!$B$11:$B$222,"*-"&Constructors!$AL21&"-*",Drivers!O$11:O$222) -> 0 | BF21: =SUMIF(Drivers!$B$11:$B$222,"*-"&Constructors!$AL21&"-*",Drivers!P$11:P$222) -> 0 | BG21: =SUM(AN21:BF21) -> 83
A22: HERT B | B22: HULLB | C22: 23 | D22: 33 | E22: 31 | F22: 0 | G22: 15 | H22: 0 | I22: 0 | J22: 0 | K22: 0 | L22: 0 | M22: 0 | N22: 0 | O22: 0 | P22: 0 | Q22: 0 | R22: 0 | S22: 0 | T22: 0 | U22: 0 | V22: 0 | W22: 79 | X22: =B22 -> HULLB | Y22: 20 | AK22: SHU Racing | AL22: SHU | AM22: 20 | AN22: =SUMIF(Drivers!$B$11:$B$222,"*-"&Constructors!$AL22&"-*",Drivers!C$11:C$222) -> 10 | AO22: =SUMIF(Drivers!$B$11:$B$222,"*-"&Constructors!$AL22&"-*",Drivers!D$11:D$222) -> 0 | AP22: 20 | AQ22: =SUMIF(Drivers!$B$11:$B$222,"*-"&Constructors!$AL22&"-*",Drivers!E$11:E$222) -> 0 | AR22: =SUMIF(Drivers!$B$11:$B$222,"*-"&Constructors!$AL22&"-*",Drivers!F$11:F$222) -> 4 | AS22: =SUMIF(Drivers!$B$11:$B$222,"*-"&Constructors!$AL22&"-*",Drivers!G$11:G$222) -> 0 | AT22: =SUMIF(Drivers!$B$11:$B$222,"*-"&Constructors!$AL22&"-*",Drivers!H$11:H$222) -> 0 | AV22: =SUMIF(Drivers!$B$11:$B$222,"*-"&Constructors!$AL22&"-*",Drivers!I$11:I$222) -> 0 | AW22: =SUMIF(Drivers!$B$11:$B$222,"*-"&Constructors!$AL22&"-*",Drivers!J$11:J$222) -> 0 | AY22: =SUMIF(Drivers!$B$11:$B$222,"*-"&Constructors!$AL22&"-*",Drivers!K$11:K$222) -> 0 | AZ22: =SUMIF(Drivers!$B$11:$B$222,"*-"&Constructors!$AL22&"-*",Drivers!L$11:L$222) -> 0 | BB22: =SUMIF(Drivers!$B$11:$B$222,"*-"&Constructors!$AL22&"-*",Drivers!M$11:M$222) -> 0 | BC22: =SUMIF(Drivers!$B$11:$B$222,"*-"&Constructors!$AL22&"-*",Drivers!N$11:N$222) -> 0 | BE22: =SUMIF(Drivers!$B$11:$B$222,"*-"&Constructors!$AL22&"-*",Drivers!O$11:O$222) -> 0 | BF22: =SUMIF(Drivers!$B$11:$B$222,"*-"&Constructors!$AL22&"-*",Drivers!P$11:P$222) -> 0 | BG22: =SUM(AN22:BF22) -> 34
